2022-04-27 14:30:52,877 ERROR scheduler Exception in Enqueue Events for Site library.test
Traceback (most recent call last):
  File "env/lib/python3.8/site-packages/pymysql/connections.py", line 613, in connect
    sock = socket.create_connection(
  File "/usr/lib/python3.8/socket.py", line 808, in create_connection
    raise err
  File "/usr/lib/python3.8/socket.py", line 796, in create_connection
    sock.connect(sa)
ConnectionRefusedError: [Errno 111] Connection refused

During handling of the above exception, another exception occurred:

Traceback (most recent call last):
  File "apps/frappe/frappe/utils/scheduler.py", line 76, in enqueue_events_for_site
    if is_scheduler_inactive():
  File "apps/frappe/frappe/utils/scheduler.py", line 113, in is_scheduler_inactive
    if is_scheduler_disabled():
  File "apps/frappe/frappe/utils/scheduler.py", line 125, in is_scheduler_disabled
    frappe.db.get_single_value("System Settings", "enable_scheduler")
  File "apps/frappe/frappe/database/database.py", line 671, in get_single_value
    val = self.query.get_sql(
  File "apps/frappe/frappe/query_builder/utils.py", line 71, in execute_query
    return frappe.db.sql(query, params, *args, **kwargs)  # nosemgrep
  File "apps/frappe/frappe/database/database.py", line 145, in sql
    self.connect()
  File "apps/frappe/frappe/database/database.py", line 76, in connect
    self._conn = self.get_connection()
  File "apps/frappe/frappe/database/mariadb/database.py", line 78, in get_connection
    conn = pymysql.connect(
  File "env/lib/python3.8/site-packages/pymysql/connections.py", line 353, in __init__
    self.connect()
  File "env/lib/python3.8/site-packages/pymysql/connections.py", line 664, in connect
    raise exc
pymysql.err.OperationalError: (2003, "Can't connect to MySQL server on '127.0.0.1' ([Errno 111] Connection refused)")

2022-04-27 14:31:53,014 ERROR scheduler Exception in Enqueue Events for Site library.test
Traceback (most recent call last):
  File "env/lib/python3.8/site-packages/pymysql/connections.py", line 613, in connect
    sock = socket.create_connection(
  File "/usr/lib/python3.8/socket.py", line 808, in create_connection
    raise err
  File "/usr/lib/python3.8/socket.py", line 796, in create_connection
    sock.connect(sa)
ConnectionRefusedError: [Errno 111] Connection refused

During handling of the above exception, another exception occurred:

Traceback (most recent call last):
  File "apps/frappe/frappe/utils/scheduler.py", line 76, in enqueue_events_for_site
    if is_scheduler_inactive():
  File "apps/frappe/frappe/utils/scheduler.py", line 113, in is_scheduler_inactive
    if is_scheduler_disabled():
  File "apps/frappe/frappe/utils/scheduler.py", line 125, in is_scheduler_disabled
    frappe.db.get_single_value("System Settings", "enable_scheduler")
  File "apps/frappe/frappe/database/database.py", line 671, in get_single_value
    val = self.query.get_sql(
  File "apps/frappe/frappe/query_builder/utils.py", line 71, in execute_query
    return frappe.db.sql(query, params, *args, **kwargs)  # nosemgrep
  File "apps/frappe/frappe/database/database.py", line 145, in sql
    self.connect()
  File "apps/frappe/frappe/database/database.py", line 76, in connect
    self._conn = self.get_connection()
  File "apps/frappe/frappe/database/mariadb/database.py", line 78, in get_connection
    conn = pymysql.connect(
  File "env/lib/python3.8/site-packages/pymysql/connections.py", line 353, in __init__
    self.connect()
  File "env/lib/python3.8/site-packages/pymysql/connections.py", line 664, in connect
    raise exc
pymysql.err.OperationalError: (2003, "Can't connect to MySQL server on '127.0.0.1' ([Errno 111] Connection refused)")

2022-04-27 14:32:53,117 ERROR scheduler Exception in Enqueue Events for Site library.test
Traceback (most recent call last):
  File "env/lib/python3.8/site-packages/pymysql/connections.py", line 613, in connect
    sock = socket.create_connection(
  File "/usr/lib/python3.8/socket.py", line 808, in create_connection
    raise err
  File "/usr/lib/python3.8/socket.py", line 796, in create_connection
    sock.connect(sa)
ConnectionRefusedError: [Errno 111] Connection refused

During handling of the above exception, another exception occurred:

Traceback (most recent call last):
  File "apps/frappe/frappe/utils/scheduler.py", line 76, in enqueue_events_for_site
    if is_scheduler_inactive():
  File "apps/frappe/frappe/utils/scheduler.py", line 113, in is_scheduler_inactive
    if is_scheduler_disabled():
  File "apps/frappe/frappe/utils/scheduler.py", line 125, in is_scheduler_disabled
    frappe.db.get_single_value("System Settings", "enable_scheduler")
  File "apps/frappe/frappe/database/database.py", line 671, in get_single_value
    val = self.query.get_sql(
  File "apps/frappe/frappe/query_builder/utils.py", line 71, in execute_query
    return frappe.db.sql(query, params, *args, **kwargs)  # nosemgrep
  File "apps/frappe/frappe/database/database.py", line 145, in sql
    self.connect()
  File "apps/frappe/frappe/database/database.py", line 76, in connect
    self._conn = self.get_connection()
  File "apps/frappe/frappe/database/mariadb/database.py", line 78, in get_connection
    conn = pymysql.connect(
  File "env/lib/python3.8/site-packages/pymysql/connections.py", line 353, in __init__
    self.connect()
  File "env/lib/python3.8/site-packages/pymysql/connections.py", line 664, in connect
    raise exc
pymysql.err.OperationalError: (2003, "Can't connect to MySQL server on '127.0.0.1' ([Errno 111] Connection refused)")

2022-04-27 14:33:53,196 ERROR scheduler Exception in Enqueue Events for Site library.test
Traceback (most recent call last):
  File "env/lib/python3.8/site-packages/pymysql/connections.py", line 613, in connect
    sock = socket.create_connection(
  File "/usr/lib/python3.8/socket.py", line 808, in create_connection
    raise err
  File "/usr/lib/python3.8/socket.py", line 796, in create_connection
    sock.connect(sa)
ConnectionRefusedError: [Errno 111] Connection refused

During handling of the above exception, another exception occurred:

Traceback (most recent call last):
  File "apps/frappe/frappe/utils/scheduler.py", line 76, in enqueue_events_for_site
    if is_scheduler_inactive():
  File "apps/frappe/frappe/utils/scheduler.py", line 113, in is_scheduler_inactive
    if is_scheduler_disabled():
  File "apps/frappe/frappe/utils/scheduler.py", line 125, in is_scheduler_disabled
    frappe.db.get_single_value("System Settings", "enable_scheduler")
  File "apps/frappe/frappe/database/database.py", line 671, in get_single_value
    val = self.query.get_sql(
  File "apps/frappe/frappe/query_builder/utils.py", line 71, in execute_query
    return frappe.db.sql(query, params, *args, **kwargs)  # nosemgrep
  File "apps/frappe/frappe/database/database.py", line 145, in sql
    self.connect()
  File "apps/frappe/frappe/database/database.py", line 76, in connect
    self._conn = self.get_connection()
  File "apps/frappe/frappe/database/mariadb/database.py", line 78, in get_connection
    conn = pymysql.connect(
  File "env/lib/python3.8/site-packages/pymysql/connections.py", line 353, in __init__
    self.connect()
  File "env/lib/python3.8/site-packages/pymysql/connections.py", line 664, in connect
    raise exc
pymysql.err.OperationalError: (2003, "Can't connect to MySQL server on '127.0.0.1' ([Errno 111] Connection refused)")

2022-04-27 14:34:53,296 ERROR scheduler Exception in Enqueue Events for Site library.test
Traceback (most recent call last):
  File "env/lib/python3.8/site-packages/pymysql/connections.py", line 613, in connect
    sock = socket.create_connection(
  File "/usr/lib/python3.8/socket.py", line 808, in create_connection
    raise err
  File "/usr/lib/python3.8/socket.py", line 796, in create_connection
    sock.connect(sa)
ConnectionRefusedError: [Errno 111] Connection refused

During handling of the above exception, another exception occurred:

Traceback (most recent call last):
  File "apps/frappe/frappe/utils/scheduler.py", line 76, in enqueue_events_for_site
    if is_scheduler_inactive():
  File "apps/frappe/frappe/utils/scheduler.py", line 113, in is_scheduler_inactive
    if is_scheduler_disabled():
  File "apps/frappe/frappe/utils/scheduler.py", line 125, in is_scheduler_disabled
    frappe.db.get_single_value("System Settings", "enable_scheduler")
  File "apps/frappe/frappe/database/database.py", line 671, in get_single_value
    val = self.query.get_sql(
  File "apps/frappe/frappe/query_builder/utils.py", line 71, in execute_query
    return frappe.db.sql(query, params, *args, **kwargs)  # nosemgrep
  File "apps/frappe/frappe/database/database.py", line 145, in sql
    self.connect()
  File "apps/frappe/frappe/database/database.py", line 76, in connect
    self._conn = self.get_connection()
  File "apps/frappe/frappe/database/mariadb/database.py", line 78, in get_connection
    conn = pymysql.connect(
  File "env/lib/python3.8/site-packages/pymysql/connections.py", line 353, in __init__
    self.connect()
  File "env/lib/python3.8/site-packages/pymysql/connections.py", line 664, in connect
    raise exc
pymysql.err.OperationalError: (2003, "Can't connect to MySQL server on '127.0.0.1' ([Errno 111] Connection refused)")

2022-04-27 14:35:53,422 ERROR scheduler Exception in Enqueue Events for Site library.test
Traceback (most recent call last):
  File "env/lib/python3.8/site-packages/pymysql/connections.py", line 613, in connect
    sock = socket.create_connection(
  File "/usr/lib/python3.8/socket.py", line 808, in create_connection
    raise err
  File "/usr/lib/python3.8/socket.py", line 796, in create_connection
    sock.connect(sa)
ConnectionRefusedError: [Errno 111] Connection refused

During handling of the above exception, another exception occurred:

Traceback (most recent call last):
  File "apps/frappe/frappe/utils/scheduler.py", line 76, in enqueue_events_for_site
    if is_scheduler_inactive():
  File "apps/frappe/frappe/utils/scheduler.py", line 113, in is_scheduler_inactive
    if is_scheduler_disabled():
  File "apps/frappe/frappe/utils/scheduler.py", line 125, in is_scheduler_disabled
    frappe.db.get_single_value("System Settings", "enable_scheduler")
  File "apps/frappe/frappe/database/database.py", line 671, in get_single_value
    val = self.query.get_sql(
  File "apps/frappe/frappe/query_builder/utils.py", line 71, in execute_query
    return frappe.db.sql(query, params, *args, **kwargs)  # nosemgrep
  File "apps/frappe/frappe/database/database.py", line 145, in sql
    self.connect()
  File "apps/frappe/frappe/database/database.py", line 76, in connect
    self._conn = self.get_connection()
  File "apps/frappe/frappe/database/mariadb/database.py", line 78, in get_connection
    conn = pymysql.connect(
  File "env/lib/python3.8/site-packages/pymysql/connections.py", line 353, in __init__
    self.connect()
  File "env/lib/python3.8/site-packages/pymysql/connections.py", line 664, in connect
    raise exc
pymysql.err.OperationalError: (2003, "Can't connect to MySQL server on '127.0.0.1' ([Errno 111] Connection refused)")

2022-04-27 14:36:53,586 ERROR scheduler Exception in Enqueue Events for Site library.test
Traceback (most recent call last):
  File "env/lib/python3.8/site-packages/pymysql/connections.py", line 613, in connect
    sock = socket.create_connection(
  File "/usr/lib/python3.8/socket.py", line 808, in create_connection
    raise err
  File "/usr/lib/python3.8/socket.py", line 796, in create_connection
    sock.connect(sa)
ConnectionRefusedError: [Errno 111] Connection refused

During handling of the above exception, another exception occurred:

Traceback (most recent call last):
  File "apps/frappe/frappe/utils/scheduler.py", line 76, in enqueue_events_for_site
    if is_scheduler_inactive():
  File "apps/frappe/frappe/utils/scheduler.py", line 113, in is_scheduler_inactive
    if is_scheduler_disabled():
  File "apps/frappe/frappe/utils/scheduler.py", line 125, in is_scheduler_disabled
    frappe.db.get_single_value("System Settings", "enable_scheduler")
  File "apps/frappe/frappe/database/database.py", line 671, in get_single_value
    val = self.query.get_sql(
  File "apps/frappe/frappe/query_builder/utils.py", line 71, in execute_query
    return frappe.db.sql(query, params, *args, **kwargs)  # nosemgrep
  File "apps/frappe/frappe/database/database.py", line 145, in sql
    self.connect()
  File "apps/frappe/frappe/database/database.py", line 76, in connect
    self._conn = self.get_connection()
  File "apps/frappe/frappe/database/mariadb/database.py", line 78, in get_connection
    conn = pymysql.connect(
  File "env/lib/python3.8/site-packages/pymysql/connections.py", line 353, in __init__
    self.connect()
  File "env/lib/python3.8/site-packages/pymysql/connections.py", line 664, in connect
    raise exc
pymysql.err.OperationalError: (2003, "Can't connect to MySQL server on '127.0.0.1' ([Errno 111] Connection refused)")

2022-04-27 14:37:53,701 ERROR scheduler Exception in Enqueue Events for Site library.test
Traceback (most recent call last):
  File "env/lib/python3.8/site-packages/pymysql/connections.py", line 613, in connect
    sock = socket.create_connection(
  File "/usr/lib/python3.8/socket.py", line 808, in create_connection
    raise err
  File "/usr/lib/python3.8/socket.py", line 796, in create_connection
    sock.connect(sa)
ConnectionRefusedError: [Errno 111] Connection refused

During handling of the above exception, another exception occurred:

Traceback (most recent call last):
  File "apps/frappe/frappe/utils/scheduler.py", line 76, in enqueue_events_for_site
    if is_scheduler_inactive():
  File "apps/frappe/frappe/utils/scheduler.py", line 113, in is_scheduler_inactive
    if is_scheduler_disabled():
  File "apps/frappe/frappe/utils/scheduler.py", line 125, in is_scheduler_disabled
    frappe.db.get_single_value("System Settings", "enable_scheduler")
  File "apps/frappe/frappe/database/database.py", line 671, in get_single_value
    val = self.query.get_sql(
  File "apps/frappe/frappe/query_builder/utils.py", line 71, in execute_query
    return frappe.db.sql(query, params, *args, **kwargs)  # nosemgrep
  File "apps/frappe/frappe/database/database.py", line 145, in sql
    self.connect()
  File "apps/frappe/frappe/database/database.py", line 76, in connect
    self._conn = self.get_connection()
  File "apps/frappe/frappe/database/mariadb/database.py", line 78, in get_connection
    conn = pymysql.connect(
  File "env/lib/python3.8/site-packages/pymysql/connections.py", line 353, in __init__
    self.connect()
  File "env/lib/python3.8/site-packages/pymysql/connections.py", line 664, in connect
    raise exc
pymysql.err.OperationalError: (2003, "Can't connect to MySQL server on '127.0.0.1' ([Errno 111] Connection refused)")

2022-04-27 14:38:53,809 ERROR scheduler Exception in Enqueue Events for Site library.test
Traceback (most recent call last):
  File "env/lib/python3.8/site-packages/pymysql/connections.py", line 613, in connect
    sock = socket.create_connection(
  File "/usr/lib/python3.8/socket.py", line 808, in create_connection
    raise err
  File "/usr/lib/python3.8/socket.py", line 796, in create_connection
    sock.connect(sa)
ConnectionRefusedError: [Errno 111] Connection refused

During handling of the above exception, another exception occurred:

Traceback (most recent call last):
  File "apps/frappe/frappe/utils/scheduler.py", line 76, in enqueue_events_for_site
    if is_scheduler_inactive():
  File "apps/frappe/frappe/utils/scheduler.py", line 113, in is_scheduler_inactive
    if is_scheduler_disabled():
  File "apps/frappe/frappe/utils/scheduler.py", line 125, in is_scheduler_disabled
    frappe.db.get_single_value("System Settings", "enable_scheduler")
  File "apps/frappe/frappe/database/database.py", line 671, in get_single_value
    val = self.query.get_sql(
  File "apps/frappe/frappe/query_builder/utils.py", line 71, in execute_query
    return frappe.db.sql(query, params, *args, **kwargs)  # nosemgrep
  File "apps/frappe/frappe/database/database.py", line 145, in sql
    self.connect()
  File "apps/frappe/frappe/database/database.py", line 76, in connect
    self._conn = self.get_connection()
  File "apps/frappe/frappe/database/mariadb/database.py", line 78, in get_connection
    conn = pymysql.connect(
  File "env/lib/python3.8/site-packages/pymysql/connections.py", line 353, in __init__
    self.connect()
  File "env/lib/python3.8/site-packages/pymysql/connections.py", line 664, in connect
    raise exc
pymysql.err.OperationalError: (2003, "Can't connect to MySQL server on '127.0.0.1' ([Errno 111] Connection refused)")

2022-04-27 14:39:53,918 ERROR scheduler Exception in Enqueue Events for Site library.test
Traceback (most recent call last):
  File "env/lib/python3.8/site-packages/pymysql/connections.py", line 613, in connect
    sock = socket.create_connection(
  File "/usr/lib/python3.8/socket.py", line 808, in create_connection
    raise err
  File "/usr/lib/python3.8/socket.py", line 796, in create_connection
    sock.connect(sa)
ConnectionRefusedError: [Errno 111] Connection refused

During handling of the above exception, another exception occurred:

Traceback (most recent call last):
  File "apps/frappe/frappe/utils/scheduler.py", line 76, in enqueue_events_for_site
    if is_scheduler_inactive():
  File "apps/frappe/frappe/utils/scheduler.py", line 113, in is_scheduler_inactive
    if is_scheduler_disabled():
  File "apps/frappe/frappe/utils/scheduler.py", line 125, in is_scheduler_disabled
    frappe.db.get_single_value("System Settings", "enable_scheduler")
  File "apps/frappe/frappe/database/database.py", line 671, in get_single_value
    val = self.query.get_sql(
  File "apps/frappe/frappe/query_builder/utils.py", line 71, in execute_query
    return frappe.db.sql(query, params, *args, **kwargs)  # nosemgrep
  File "apps/frappe/frappe/database/database.py", line 145, in sql
    self.connect()
  File "apps/frappe/frappe/database/database.py", line 76, in connect
    self._conn = self.get_connection()
  File "apps/frappe/frappe/database/mariadb/database.py", line 78, in get_connection
    conn = pymysql.connect(
  File "env/lib/python3.8/site-packages/pymysql/connections.py", line 353, in __init__
    self.connect()
  File "env/lib/python3.8/site-packages/pymysql/connections.py", line 664, in connect
    raise exc
pymysql.err.OperationalError: (2003, "Can't connect to MySQL server on '127.0.0.1' ([Errno 111] Connection refused)")

2022-04-27 14:40:54,018 ERROR scheduler Exception in Enqueue Events for Site library.test
Traceback (most recent call last):
  File "env/lib/python3.8/site-packages/pymysql/connections.py", line 613, in connect
    sock = socket.create_connection(
  File "/usr/lib/python3.8/socket.py", line 808, in create_connection
    raise err
  File "/usr/lib/python3.8/socket.py", line 796, in create_connection
    sock.connect(sa)
ConnectionRefusedError: [Errno 111] Connection refused

During handling of the above exception, another exception occurred:

Traceback (most recent call last):
  File "apps/frappe/frappe/utils/scheduler.py", line 76, in enqueue_events_for_site
    if is_scheduler_inactive():
  File "apps/frappe/frappe/utils/scheduler.py", line 113, in is_scheduler_inactive
    if is_scheduler_disabled():
  File "apps/frappe/frappe/utils/scheduler.py", line 125, in is_scheduler_disabled
    frappe.db.get_single_value("System Settings", "enable_scheduler")
  File "apps/frappe/frappe/database/database.py", line 671, in get_single_value
    val = self.query.get_sql(
  File "apps/frappe/frappe/query_builder/utils.py", line 71, in execute_query
    return frappe.db.sql(query, params, *args, **kwargs)  # nosemgrep
  File "apps/frappe/frappe/database/database.py", line 145, in sql
    self.connect()
  File "apps/frappe/frappe/database/database.py", line 76, in connect
    self._conn = self.get_connection()
  File "apps/frappe/frappe/database/mariadb/database.py", line 78, in get_connection
    conn = pymysql.connect(
  File "env/lib/python3.8/site-packages/pymysql/connections.py", line 353, in __init__
    self.connect()
  File "env/lib/python3.8/site-packages/pymysql/connections.py", line 664, in connect
    raise exc
pymysql.err.OperationalError: (2003, "Can't connect to MySQL server on '127.0.0.1' ([Errno 111] Connection refused)")

2022-04-27 14:41:54,124 ERROR scheduler Exception in Enqueue Events for Site library.test
Traceback (most recent call last):
  File "env/lib/python3.8/site-packages/pymysql/connections.py", line 613, in connect
    sock = socket.create_connection(
  File "/usr/lib/python3.8/socket.py", line 808, in create_connection
    raise err
  File "/usr/lib/python3.8/socket.py", line 796, in create_connection
    sock.connect(sa)
ConnectionRefusedError: [Errno 111] Connection refused

During handling of the above exception, another exception occurred:

Traceback (most recent call last):
  File "apps/frappe/frappe/utils/scheduler.py", line 76, in enqueue_events_for_site
    if is_scheduler_inactive():
  File "apps/frappe/frappe/utils/scheduler.py", line 113, in is_scheduler_inactive
    if is_scheduler_disabled():
  File "apps/frappe/frappe/utils/scheduler.py", line 125, in is_scheduler_disabled
    frappe.db.get_single_value("System Settings", "enable_scheduler")
  File "apps/frappe/frappe/database/database.py", line 671, in get_single_value
    val = self.query.get_sql(
  File "apps/frappe/frappe/query_builder/utils.py", line 71, in execute_query
    return frappe.db.sql(query, params, *args, **kwargs)  # nosemgrep
  File "apps/frappe/frappe/database/database.py", line 145, in sql
    self.connect()
  File "apps/frappe/frappe/database/database.py", line 76, in connect
    self._conn = self.get_connection()
  File "apps/frappe/frappe/database/mariadb/database.py", line 78, in get_connection
    conn = pymysql.connect(
  File "env/lib/python3.8/site-packages/pymysql/connections.py", line 353, in __init__
    self.connect()
  File "env/lib/python3.8/site-packages/pymysql/connections.py", line 664, in connect
    raise exc
pymysql.err.OperationalError: (2003, "Can't connect to MySQL server on '127.0.0.1' ([Errno 111] Connection refused)")

2022-04-27 14:42:54,242 ERROR scheduler Exception in Enqueue Events for Site library.test
Traceback (most recent call last):
  File "env/lib/python3.8/site-packages/pymysql/connections.py", line 613, in connect
    sock = socket.create_connection(
  File "/usr/lib/python3.8/socket.py", line 808, in create_connection
    raise err
  File "/usr/lib/python3.8/socket.py", line 796, in create_connection
    sock.connect(sa)
ConnectionRefusedError: [Errno 111] Connection refused

During handling of the above exception, another exception occurred:

Traceback (most recent call last):
  File "apps/frappe/frappe/utils/scheduler.py", line 76, in enqueue_events_for_site
    if is_scheduler_inactive():
  File "apps/frappe/frappe/utils/scheduler.py", line 113, in is_scheduler_inactive
    if is_scheduler_disabled():
  File "apps/frappe/frappe/utils/scheduler.py", line 125, in is_scheduler_disabled
    frappe.db.get_single_value("System Settings", "enable_scheduler")
  File "apps/frappe/frappe/database/database.py", line 671, in get_single_value
    val = self.query.get_sql(
  File "apps/frappe/frappe/query_builder/utils.py", line 71, in execute_query
    return frappe.db.sql(query, params, *args, **kwargs)  # nosemgrep
  File "apps/frappe/frappe/database/database.py", line 145, in sql
    self.connect()
  File "apps/frappe/frappe/database/database.py", line 76, in connect
    self._conn = self.get_connection()
  File "apps/frappe/frappe/database/mariadb/database.py", line 78, in get_connection
    conn = pymysql.connect(
  File "env/lib/python3.8/site-packages/pymysql/connections.py", line 353, in __init__
    self.connect()
  File "env/lib/python3.8/site-packages/pymysql/connections.py", line 664, in connect
    raise exc
pymysql.err.OperationalError: (2003, "Can't connect to MySQL server on '127.0.0.1' ([Errno 111] Connection refused)")

2022-04-27 14:43:54,344 ERROR scheduler Exception in Enqueue Events for Site library.test
Traceback (most recent call last):
  File "env/lib/python3.8/site-packages/pymysql/connections.py", line 613, in connect
    sock = socket.create_connection(
  File "/usr/lib/python3.8/socket.py", line 808, in create_connection
    raise err
  File "/usr/lib/python3.8/socket.py", line 796, in create_connection
    sock.connect(sa)
ConnectionRefusedError: [Errno 111] Connection refused

During handling of the above exception, another exception occurred:

Traceback (most recent call last):
  File "apps/frappe/frappe/utils/scheduler.py", line 76, in enqueue_events_for_site
    if is_scheduler_inactive():
  File "apps/frappe/frappe/utils/scheduler.py", line 113, in is_scheduler_inactive
    if is_scheduler_disabled():
  File "apps/frappe/frappe/utils/scheduler.py", line 125, in is_scheduler_disabled
    frappe.db.get_single_value("System Settings", "enable_scheduler")
  File "apps/frappe/frappe/database/database.py", line 671, in get_single_value
    val = self.query.get_sql(
  File "apps/frappe/frappe/query_builder/utils.py", line 71, in execute_query
    return frappe.db.sql(query, params, *args, **kwargs)  # nosemgrep
  File "apps/frappe/frappe/database/database.py", line 145, in sql
    self.connect()
  File "apps/frappe/frappe/database/database.py", line 76, in connect
    self._conn = self.get_connection()
  File "apps/frappe/frappe/database/mariadb/database.py", line 78, in get_connection
    conn = pymysql.connect(
  File "env/lib/python3.8/site-packages/pymysql/connections.py", line 353, in __init__
    self.connect()
  File "env/lib/python3.8/site-packages/pymysql/connections.py", line 664, in connect
    raise exc
pymysql.err.OperationalError: (2003, "Can't connect to MySQL server on '127.0.0.1' ([Errno 111] Connection refused)")

2022-04-27 14:44:54,464 ERROR scheduler Exception in Enqueue Events for Site library.test
Traceback (most recent call last):
  File "env/lib/python3.8/site-packages/pymysql/connections.py", line 613, in connect
    sock = socket.create_connection(
  File "/usr/lib/python3.8/socket.py", line 808, in create_connection
    raise err
  File "/usr/lib/python3.8/socket.py", line 796, in create_connection
    sock.connect(sa)
ConnectionRefusedError: [Errno 111] Connection refused

During handling of the above exception, another exception occurred:

Traceback (most recent call last):
  File "apps/frappe/frappe/utils/scheduler.py", line 76, in enqueue_events_for_site
    if is_scheduler_inactive():
  File "apps/frappe/frappe/utils/scheduler.py", line 113, in is_scheduler_inactive
    if is_scheduler_disabled():
  File "apps/frappe/frappe/utils/scheduler.py", line 125, in is_scheduler_disabled
    frappe.db.get_single_value("System Settings", "enable_scheduler")
  File "apps/frappe/frappe/database/database.py", line 671, in get_single_value
    val = self.query.get_sql(
  File "apps/frappe/frappe/query_builder/utils.py", line 71, in execute_query
    return frappe.db.sql(query, params, *args, **kwargs)  # nosemgrep
  File "apps/frappe/frappe/database/database.py", line 145, in sql
    self.connect()
  File "apps/frappe/frappe/database/database.py", line 76, in connect
    self._conn = self.get_connection()
  File "apps/frappe/frappe/database/mariadb/database.py", line 78, in get_connection
    conn = pymysql.connect(
  File "env/lib/python3.8/site-packages/pymysql/connections.py", line 353, in __init__
    self.connect()
  File "env/lib/python3.8/site-packages/pymysql/connections.py", line 664, in connect
    raise exc
pymysql.err.OperationalError: (2003, "Can't connect to MySQL server on '127.0.0.1' ([Errno 111] Connection refused)")

2022-04-27 14:45:54,572 ERROR scheduler Exception in Enqueue Events for Site library.test
Traceback (most recent call last):
  File "env/lib/python3.8/site-packages/pymysql/connections.py", line 613, in connect
    sock = socket.create_connection(
  File "/usr/lib/python3.8/socket.py", line 808, in create_connection
    raise err
  File "/usr/lib/python3.8/socket.py", line 796, in create_connection
    sock.connect(sa)
ConnectionRefusedError: [Errno 111] Connection refused

During handling of the above exception, another exception occurred:

Traceback (most recent call last):
  File "apps/frappe/frappe/utils/scheduler.py", line 76, in enqueue_events_for_site
    if is_scheduler_inactive():
  File "apps/frappe/frappe/utils/scheduler.py", line 113, in is_scheduler_inactive
    if is_scheduler_disabled():
  File "apps/frappe/frappe/utils/scheduler.py", line 125, in is_scheduler_disabled
    frappe.db.get_single_value("System Settings", "enable_scheduler")
  File "apps/frappe/frappe/database/database.py", line 671, in get_single_value
    val = self.query.get_sql(
  File "apps/frappe/frappe/query_builder/utils.py", line 71, in execute_query
    return frappe.db.sql(query, params, *args, **kwargs)  # nosemgrep
  File "apps/frappe/frappe/database/database.py", line 145, in sql
    self.connect()
  File "apps/frappe/frappe/database/database.py", line 76, in connect
    self._conn = self.get_connection()
  File "apps/frappe/frappe/database/mariadb/database.py", line 78, in get_connection
    conn = pymysql.connect(
  File "env/lib/python3.8/site-packages/pymysql/connections.py", line 353, in __init__
    self.connect()
  File "env/lib/python3.8/site-packages/pymysql/connections.py", line 664, in connect
    raise exc
pymysql.err.OperationalError: (2003, "Can't connect to MySQL server on '127.0.0.1' ([Errno 111] Connection refused)")

2022-04-27 14:46:54,676 ERROR scheduler Exception in Enqueue Events for Site library.test
Traceback (most recent call last):
  File "env/lib/python3.8/site-packages/pymysql/connections.py", line 613, in connect
    sock = socket.create_connection(
  File "/usr/lib/python3.8/socket.py", line 808, in create_connection
    raise err
  File "/usr/lib/python3.8/socket.py", line 796, in create_connection
    sock.connect(sa)
ConnectionRefusedError: [Errno 111] Connection refused

During handling of the above exception, another exception occurred:

Traceback (most recent call last):
  File "apps/frappe/frappe/utils/scheduler.py", line 76, in enqueue_events_for_site
    if is_scheduler_inactive():
  File "apps/frappe/frappe/utils/scheduler.py", line 113, in is_scheduler_inactive
    if is_scheduler_disabled():
  File "apps/frappe/frappe/utils/scheduler.py", line 125, in is_scheduler_disabled
    frappe.db.get_single_value("System Settings", "enable_scheduler")
  File "apps/frappe/frappe/database/database.py", line 671, in get_single_value
    val = self.query.get_sql(
  File "apps/frappe/frappe/query_builder/utils.py", line 71, in execute_query
    return frappe.db.sql(query, params, *args, **kwargs)  # nosemgrep
  File "apps/frappe/frappe/database/database.py", line 145, in sql
    self.connect()
  File "apps/frappe/frappe/database/database.py", line 76, in connect
    self._conn = self.get_connection()
  File "apps/frappe/frappe/database/mariadb/database.py", line 78, in get_connection
    conn = pymysql.connect(
  File "env/lib/python3.8/site-packages/pymysql/connections.py", line 353, in __init__
    self.connect()
  File "env/lib/python3.8/site-packages/pymysql/connections.py", line 664, in connect
    raise exc
pymysql.err.OperationalError: (2003, "Can't connect to MySQL server on '127.0.0.1' ([Errno 111] Connection refused)")

2022-04-27 14:47:54,764 ERROR scheduler Exception in Enqueue Events for Site library.test
Traceback (most recent call last):
  File "env/lib/python3.8/site-packages/pymysql/connections.py", line 613, in connect
    sock = socket.create_connection(
  File "/usr/lib/python3.8/socket.py", line 808, in create_connection
    raise err
  File "/usr/lib/python3.8/socket.py", line 796, in create_connection
    sock.connect(sa)
ConnectionRefusedError: [Errno 111] Connection refused

During handling of the above exception, another exception occurred:

Traceback (most recent call last):
  File "apps/frappe/frappe/utils/scheduler.py", line 76, in enqueue_events_for_site
    if is_scheduler_inactive():
  File "apps/frappe/frappe/utils/scheduler.py", line 113, in is_scheduler_inactive
    if is_scheduler_disabled():
  File "apps/frappe/frappe/utils/scheduler.py", line 125, in is_scheduler_disabled
    frappe.db.get_single_value("System Settings", "enable_scheduler")
  File "apps/frappe/frappe/database/database.py", line 671, in get_single_value
    val = self.query.get_sql(
  File "apps/frappe/frappe/query_builder/utils.py", line 71, in execute_query
    return frappe.db.sql(query, params, *args, **kwargs)  # nosemgrep
  File "apps/frappe/frappe/database/database.py", line 145, in sql
    self.connect()
  File "apps/frappe/frappe/database/database.py", line 76, in connect
    self._conn = self.get_connection()
  File "apps/frappe/frappe/database/mariadb/database.py", line 78, in get_connection
    conn = pymysql.connect(
  File "env/lib/python3.8/site-packages/pymysql/connections.py", line 353, in __init__
    self.connect()
  File "env/lib/python3.8/site-packages/pymysql/connections.py", line 664, in connect
    raise exc
pymysql.err.OperationalError: (2003, "Can't connect to MySQL server on '127.0.0.1' ([Errno 111] Connection refused)")

2022-04-27 14:48:54,852 ERROR scheduler Exception in Enqueue Events for Site library.test
Traceback (most recent call last):
  File "env/lib/python3.8/site-packages/pymysql/connections.py", line 613, in connect
    sock = socket.create_connection(
  File "/usr/lib/python3.8/socket.py", line 808, in create_connection
    raise err
  File "/usr/lib/python3.8/socket.py", line 796, in create_connection
    sock.connect(sa)
ConnectionRefusedError: [Errno 111] Connection refused

During handling of the above exception, another exception occurred:

Traceback (most recent call last):
  File "apps/frappe/frappe/utils/scheduler.py", line 76, in enqueue_events_for_site
    if is_scheduler_inactive():
  File "apps/frappe/frappe/utils/scheduler.py", line 113, in is_scheduler_inactive
    if is_scheduler_disabled():
  File "apps/frappe/frappe/utils/scheduler.py", line 125, in is_scheduler_disabled
    frappe.db.get_single_value("System Settings", "enable_scheduler")
  File "apps/frappe/frappe/database/database.py", line 671, in get_single_value
    val = self.query.get_sql(
  File "apps/frappe/frappe/query_builder/utils.py", line 71, in execute_query
    return frappe.db.sql(query, params, *args, **kwargs)  # nosemgrep
  File "apps/frappe/frappe/database/database.py", line 145, in sql
    self.connect()
  File "apps/frappe/frappe/database/database.py", line 76, in connect
    self._conn = self.get_connection()
  File "apps/frappe/frappe/database/mariadb/database.py", line 78, in get_connection
    conn = pymysql.connect(
  File "env/lib/python3.8/site-packages/pymysql/connections.py", line 353, in __init__
    self.connect()
  File "env/lib/python3.8/site-packages/pymysql/connections.py", line 664, in connect
    raise exc
pymysql.err.OperationalError: (2003, "Can't connect to MySQL server on '127.0.0.1' ([Errno 111] Connection refused)")

2022-04-27 14:49:54,984 ERROR scheduler Exception in Enqueue Events for Site library.test
Traceback (most recent call last):
  File "env/lib/python3.8/site-packages/pymysql/connections.py", line 613, in connect
    sock = socket.create_connection(
  File "/usr/lib/python3.8/socket.py", line 808, in create_connection
    raise err
  File "/usr/lib/python3.8/socket.py", line 796, in create_connection
    sock.connect(sa)
ConnectionRefusedError: [Errno 111] Connection refused

During handling of the above exception, another exception occurred:

Traceback (most recent call last):
  File "apps/frappe/frappe/utils/scheduler.py", line 76, in enqueue_events_for_site
    if is_scheduler_inactive():
  File "apps/frappe/frappe/utils/scheduler.py", line 113, in is_scheduler_inactive
    if is_scheduler_disabled():
  File "apps/frappe/frappe/utils/scheduler.py", line 125, in is_scheduler_disabled
    frappe.db.get_single_value("System Settings", "enable_scheduler")
  File "apps/frappe/frappe/database/database.py", line 671, in get_single_value
    val = self.query.get_sql(
  File "apps/frappe/frappe/query_builder/utils.py", line 71, in execute_query
    return frappe.db.sql(query, params, *args, **kwargs)  # nosemgrep
  File "apps/frappe/frappe/database/database.py", line 145, in sql
    self.connect()
  File "apps/frappe/frappe/database/database.py", line 76, in connect
    self._conn = self.get_connection()
  File "apps/frappe/frappe/database/mariadb/database.py", line 78, in get_connection
    conn = pymysql.connect(
  File "env/lib/python3.8/site-packages/pymysql/connections.py", line 353, in __init__
    self.connect()
  File "env/lib/python3.8/site-packages/pymysql/connections.py", line 664, in connect
    raise exc
pymysql.err.OperationalError: (2003, "Can't connect to MySQL server on '127.0.0.1' ([Errno 111] Connection refused)")

2022-04-27 14:50:55,104 ERROR scheduler Exception in Enqueue Events for Site library.test
Traceback (most recent call last):
  File "env/lib/python3.8/site-packages/pymysql/connections.py", line 613, in connect
    sock = socket.create_connection(
  File "/usr/lib/python3.8/socket.py", line 808, in create_connection
    raise err
  File "/usr/lib/python3.8/socket.py", line 796, in create_connection
    sock.connect(sa)
ConnectionRefusedError: [Errno 111] Connection refused

During handling of the above exception, another exception occurred:

Traceback (most recent call last):
  File "apps/frappe/frappe/utils/scheduler.py", line 76, in enqueue_events_for_site
    if is_scheduler_inactive():
  File "apps/frappe/frappe/utils/scheduler.py", line 113, in is_scheduler_inactive
    if is_scheduler_disabled():
  File "apps/frappe/frappe/utils/scheduler.py", line 125, in is_scheduler_disabled
    frappe.db.get_single_value("System Settings", "enable_scheduler")
  File "apps/frappe/frappe/database/database.py", line 671, in get_single_value
    val = self.query.get_sql(
  File "apps/frappe/frappe/query_builder/utils.py", line 71, in execute_query
    return frappe.db.sql(query, params, *args, **kwargs)  # nosemgrep
  File "apps/frappe/frappe/database/database.py", line 145, in sql
    self.connect()
  File "apps/frappe/frappe/database/database.py", line 76, in connect
    self._conn = self.get_connection()
  File "apps/frappe/frappe/database/mariadb/database.py", line 78, in get_connection
    conn = pymysql.connect(
  File "env/lib/python3.8/site-packages/pymysql/connections.py", line 353, in __init__
    self.connect()
  File "env/lib/python3.8/site-packages/pymysql/connections.py", line 664, in connect
    raise exc
pymysql.err.OperationalError: (2003, "Can't connect to MySQL server on '127.0.0.1' ([Errno 111] Connection refused)")

2022-04-27 14:51:55,250 ERROR scheduler Exception in Enqueue Events for Site library.test
Traceback (most recent call last):
  File "env/lib/python3.8/site-packages/pymysql/connections.py", line 613, in connect
    sock = socket.create_connection(
  File "/usr/lib/python3.8/socket.py", line 808, in create_connection
    raise err
  File "/usr/lib/python3.8/socket.py", line 796, in create_connection
    sock.connect(sa)
ConnectionRefusedError: [Errno 111] Connection refused

During handling of the above exception, another exception occurred:

Traceback (most recent call last):
  File "apps/frappe/frappe/utils/scheduler.py", line 76, in enqueue_events_for_site
    if is_scheduler_inactive():
  File "apps/frappe/frappe/utils/scheduler.py", line 113, in is_scheduler_inactive
    if is_scheduler_disabled():
  File "apps/frappe/frappe/utils/scheduler.py", line 125, in is_scheduler_disabled
    frappe.db.get_single_value("System Settings", "enable_scheduler")
  File "apps/frappe/frappe/database/database.py", line 671, in get_single_value
    val = self.query.get_sql(
  File "apps/frappe/frappe/query_builder/utils.py", line 71, in execute_query
    return frappe.db.sql(query, params, *args, **kwargs)  # nosemgrep
  File "apps/frappe/frappe/database/database.py", line 145, in sql
    self.connect()
  File "apps/frappe/frappe/database/database.py", line 76, in connect
    self._conn = self.get_connection()
  File "apps/frappe/frappe/database/mariadb/database.py", line 78, in get_connection
    conn = pymysql.connect(
  File "env/lib/python3.8/site-packages/pymysql/connections.py", line 353, in __init__
    self.connect()
  File "env/lib/python3.8/site-packages/pymysql/connections.py", line 664, in connect
    raise exc
pymysql.err.OperationalError: (2003, "Can't connect to MySQL server on '127.0.0.1' ([Errno 111] Connection refused)")

2022-04-27 14:52:55,368 ERROR scheduler Exception in Enqueue Events for Site library.test
Traceback (most recent call last):
  File "env/lib/python3.8/site-packages/pymysql/connections.py", line 613, in connect
    sock = socket.create_connection(
  File "/usr/lib/python3.8/socket.py", line 808, in create_connection
    raise err
  File "/usr/lib/python3.8/socket.py", line 796, in create_connection
    sock.connect(sa)
ConnectionRefusedError: [Errno 111] Connection refused

During handling of the above exception, another exception occurred:

Traceback (most recent call last):
  File "apps/frappe/frappe/utils/scheduler.py", line 76, in enqueue_events_for_site
    if is_scheduler_inactive():
  File "apps/frappe/frappe/utils/scheduler.py", line 113, in is_scheduler_inactive
    if is_scheduler_disabled():
  File "apps/frappe/frappe/utils/scheduler.py", line 125, in is_scheduler_disabled
    frappe.db.get_single_value("System Settings", "enable_scheduler")
  File "apps/frappe/frappe/database/database.py", line 671, in get_single_value
    val = self.query.get_sql(
  File "apps/frappe/frappe/query_builder/utils.py", line 71, in execute_query
    return frappe.db.sql(query, params, *args, **kwargs)  # nosemgrep
  File "apps/frappe/frappe/database/database.py", line 145, in sql
    self.connect()
  File "apps/frappe/frappe/database/database.py", line 76, in connect
    self._conn = self.get_connection()
  File "apps/frappe/frappe/database/mariadb/database.py", line 78, in get_connection
    conn = pymysql.connect(
  File "env/lib/python3.8/site-packages/pymysql/connections.py", line 353, in __init__
    self.connect()
  File "env/lib/python3.8/site-packages/pymysql/connections.py", line 664, in connect
    raise exc
pymysql.err.OperationalError: (2003, "Can't connect to MySQL server on '127.0.0.1' ([Errno 111] Connection refused)")

2022-04-27 14:53:55,472 ERROR scheduler Exception in Enqueue Events for Site library.test
Traceback (most recent call last):
  File "env/lib/python3.8/site-packages/pymysql/connections.py", line 613, in connect
    sock = socket.create_connection(
  File "/usr/lib/python3.8/socket.py", line 808, in create_connection
    raise err
  File "/usr/lib/python3.8/socket.py", line 796, in create_connection
    sock.connect(sa)
ConnectionRefusedError: [Errno 111] Connection refused

During handling of the above exception, another exception occurred:

Traceback (most recent call last):
  File "apps/frappe/frappe/utils/scheduler.py", line 76, in enqueue_events_for_site
    if is_scheduler_inactive():
  File "apps/frappe/frappe/utils/scheduler.py", line 113, in is_scheduler_inactive
    if is_scheduler_disabled():
  File "apps/frappe/frappe/utils/scheduler.py", line 125, in is_scheduler_disabled
    frappe.db.get_single_value("System Settings", "enable_scheduler")
  File "apps/frappe/frappe/database/database.py", line 671, in get_single_value
    val = self.query.get_sql(
  File "apps/frappe/frappe/query_builder/utils.py", line 71, in execute_query
    return frappe.db.sql(query, params, *args, **kwargs)  # nosemgrep
  File "apps/frappe/frappe/database/database.py", line 145, in sql
    self.connect()
  File "apps/frappe/frappe/database/database.py", line 76, in connect
    self._conn = self.get_connection()
  File "apps/frappe/frappe/database/mariadb/database.py", line 78, in get_connection
    conn = pymysql.connect(
  File "env/lib/python3.8/site-packages/pymysql/connections.py", line 353, in __init__
    self.connect()
  File "env/lib/python3.8/site-packages/pymysql/connections.py", line 664, in connect
    raise exc
pymysql.err.OperationalError: (2003, "Can't connect to MySQL server on '127.0.0.1' ([Errno 111] Connection refused)")

2022-04-27 14:54:55,627 ERROR scheduler Exception in Enqueue Events for Site library.test
Traceback (most recent call last):
  File "env/lib/python3.8/site-packages/pymysql/connections.py", line 613, in connect
    sock = socket.create_connection(
  File "/usr/lib/python3.8/socket.py", line 808, in create_connection
    raise err
  File "/usr/lib/python3.8/socket.py", line 796, in create_connection
    sock.connect(sa)
ConnectionRefusedError: [Errno 111] Connection refused

During handling of the above exception, another exception occurred:

Traceback (most recent call last):
  File "apps/frappe/frappe/utils/scheduler.py", line 76, in enqueue_events_for_site
    if is_scheduler_inactive():
  File "apps/frappe/frappe/utils/scheduler.py", line 113, in is_scheduler_inactive
    if is_scheduler_disabled():
  File "apps/frappe/frappe/utils/scheduler.py", line 125, in is_scheduler_disabled
    frappe.db.get_single_value("System Settings", "enable_scheduler")
  File "apps/frappe/frappe/database/database.py", line 671, in get_single_value
    val = self.query.get_sql(
  File "apps/frappe/frappe/query_builder/utils.py", line 71, in execute_query
    return frappe.db.sql(query, params, *args, **kwargs)  # nosemgrep
  File "apps/frappe/frappe/database/database.py", line 145, in sql
    self.connect()
  File "apps/frappe/frappe/database/database.py", line 76, in connect
    self._conn = self.get_connection()
  File "apps/frappe/frappe/database/mariadb/database.py", line 78, in get_connection
    conn = pymysql.connect(
  File "env/lib/python3.8/site-packages/pymysql/connections.py", line 353, in __init__
    self.connect()
  File "env/lib/python3.8/site-packages/pymysql/connections.py", line 664, in connect
    raise exc
pymysql.err.OperationalError: (2003, "Can't connect to MySQL server on '127.0.0.1' ([Errno 111] Connection refused)")

2022-04-27 14:55:55,744 ERROR scheduler Exception in Enqueue Events for Site library.test
Traceback (most recent call last):
  File "env/lib/python3.8/site-packages/pymysql/connections.py", line 613, in connect
    sock = socket.create_connection(
  File "/usr/lib/python3.8/socket.py", line 808, in create_connection
    raise err
  File "/usr/lib/python3.8/socket.py", line 796, in create_connection
    sock.connect(sa)
ConnectionRefusedError: [Errno 111] Connection refused

During handling of the above exception, another exception occurred:

Traceback (most recent call last):
  File "apps/frappe/frappe/utils/scheduler.py", line 76, in enqueue_events_for_site
    if is_scheduler_inactive():
  File "apps/frappe/frappe/utils/scheduler.py", line 113, in is_scheduler_inactive
    if is_scheduler_disabled():
  File "apps/frappe/frappe/utils/scheduler.py", line 125, in is_scheduler_disabled
    frappe.db.get_single_value("System Settings", "enable_scheduler")
  File "apps/frappe/frappe/database/database.py", line 671, in get_single_value
    val = self.query.get_sql(
  File "apps/frappe/frappe/query_builder/utils.py", line 71, in execute_query
    return frappe.db.sql(query, params, *args, **kwargs)  # nosemgrep
  File "apps/frappe/frappe/database/database.py", line 145, in sql
    self.connect()
  File "apps/frappe/frappe/database/database.py", line 76, in connect
    self._conn = self.get_connection()
  File "apps/frappe/frappe/database/mariadb/database.py", line 78, in get_connection
    conn = pymysql.connect(
  File "env/lib/python3.8/site-packages/pymysql/connections.py", line 353, in __init__
    self.connect()
  File "env/lib/python3.8/site-packages/pymysql/connections.py", line 664, in connect
    raise exc
pymysql.err.OperationalError: (2003, "Can't connect to MySQL server on '127.0.0.1' ([Errno 111] Connection refused)")

2022-04-27 14:56:55,858 ERROR scheduler Exception in Enqueue Events for Site library.test
Traceback (most recent call last):
  File "env/lib/python3.8/site-packages/pymysql/connections.py", line 613, in connect
    sock = socket.create_connection(
  File "/usr/lib/python3.8/socket.py", line 808, in create_connection
    raise err
  File "/usr/lib/python3.8/socket.py", line 796, in create_connection
    sock.connect(sa)
ConnectionRefusedError: [Errno 111] Connection refused

During handling of the above exception, another exception occurred:

Traceback (most recent call last):
  File "apps/frappe/frappe/utils/scheduler.py", line 76, in enqueue_events_for_site
    if is_scheduler_inactive():
  File "apps/frappe/frappe/utils/scheduler.py", line 113, in is_scheduler_inactive
    if is_scheduler_disabled():
  File "apps/frappe/frappe/utils/scheduler.py", line 125, in is_scheduler_disabled
    frappe.db.get_single_value("System Settings", "enable_scheduler")
  File "apps/frappe/frappe/database/database.py", line 671, in get_single_value
    val = self.query.get_sql(
  File "apps/frappe/frappe/query_builder/utils.py", line 71, in execute_query
    return frappe.db.sql(query, params, *args, **kwargs)  # nosemgrep
  File "apps/frappe/frappe/database/database.py", line 145, in sql
    self.connect()
  File "apps/frappe/frappe/database/database.py", line 76, in connect
    self._conn = self.get_connection()
  File "apps/frappe/frappe/database/mariadb/database.py", line 78, in get_connection
    conn = pymysql.connect(
  File "env/lib/python3.8/site-packages/pymysql/connections.py", line 353, in __init__
    self.connect()
  File "env/lib/python3.8/site-packages/pymysql/connections.py", line 664, in connect
    raise exc
pymysql.err.OperationalError: (2003, "Can't connect to MySQL server on '127.0.0.1' ([Errno 111] Connection refused)")

2022-04-27 14:57:55,990 ERROR scheduler Exception in Enqueue Events for Site library.test
Traceback (most recent call last):
  File "env/lib/python3.8/site-packages/pymysql/connections.py", line 613, in connect
    sock = socket.create_connection(
  File "/usr/lib/python3.8/socket.py", line 808, in create_connection
    raise err
  File "/usr/lib/python3.8/socket.py", line 796, in create_connection
    sock.connect(sa)
ConnectionRefusedError: [Errno 111] Connection refused

During handling of the above exception, another exception occurred:

Traceback (most recent call last):
  File "apps/frappe/frappe/utils/scheduler.py", line 76, in enqueue_events_for_site
    if is_scheduler_inactive():
  File "apps/frappe/frappe/utils/scheduler.py", line 113, in is_scheduler_inactive
    if is_scheduler_disabled():
  File "apps/frappe/frappe/utils/scheduler.py", line 125, in is_scheduler_disabled
    frappe.db.get_single_value("System Settings", "enable_scheduler")
  File "apps/frappe/frappe/database/database.py", line 671, in get_single_value
    val = self.query.get_sql(
  File "apps/frappe/frappe/query_builder/utils.py", line 71, in execute_query
    return frappe.db.sql(query, params, *args, **kwargs)  # nosemgrep
  File "apps/frappe/frappe/database/database.py", line 145, in sql
    self.connect()
  File "apps/frappe/frappe/database/database.py", line 76, in connect
    self._conn = self.get_connection()
  File "apps/frappe/frappe/database/mariadb/database.py", line 78, in get_connection
    conn = pymysql.connect(
  File "env/lib/python3.8/site-packages/pymysql/connections.py", line 353, in __init__
    self.connect()
  File "env/lib/python3.8/site-packages/pymysql/connections.py", line 664, in connect
    raise exc
pymysql.err.OperationalError: (2003, "Can't connect to MySQL server on '127.0.0.1' ([Errno 111] Connection refused)")

2022-04-27 14:58:56,113 ERROR scheduler Exception in Enqueue Events for Site library.test
Traceback (most recent call last):
  File "env/lib/python3.8/site-packages/pymysql/connections.py", line 613, in connect
    sock = socket.create_connection(
  File "/usr/lib/python3.8/socket.py", line 808, in create_connection
    raise err
  File "/usr/lib/python3.8/socket.py", line 796, in create_connection
    sock.connect(sa)
ConnectionRefusedError: [Errno 111] Connection refused

During handling of the above exception, another exception occurred:

Traceback (most recent call last):
  File "apps/frappe/frappe/utils/scheduler.py", line 76, in enqueue_events_for_site
    if is_scheduler_inactive():
  File "apps/frappe/frappe/utils/scheduler.py", line 113, in is_scheduler_inactive
    if is_scheduler_disabled():
  File "apps/frappe/frappe/utils/scheduler.py", line 125, in is_scheduler_disabled
    frappe.db.get_single_value("System Settings", "enable_scheduler")
  File "apps/frappe/frappe/database/database.py", line 671, in get_single_value
    val = self.query.get_sql(
  File "apps/frappe/frappe/query_builder/utils.py", line 71, in execute_query
    return frappe.db.sql(query, params, *args, **kwargs)  # nosemgrep
  File "apps/frappe/frappe/database/database.py", line 145, in sql
    self.connect()
  File "apps/frappe/frappe/database/database.py", line 76, in connect
    self._conn = self.get_connection()
  File "apps/frappe/frappe/database/mariadb/database.py", line 78, in get_connection
    conn = pymysql.connect(
  File "env/lib/python3.8/site-packages/pymysql/connections.py", line 353, in __init__
    self.connect()
  File "env/lib/python3.8/site-packages/pymysql/connections.py", line 664, in connect
    raise exc
pymysql.err.OperationalError: (2003, "Can't connect to MySQL server on '127.0.0.1' ([Errno 111] Connection refused)")

2022-04-27 14:59:56,254 ERROR scheduler Exception in Enqueue Events for Site library.test
Traceback (most recent call last):
  File "env/lib/python3.8/site-packages/pymysql/connections.py", line 613, in connect
    sock = socket.create_connection(
  File "/usr/lib/python3.8/socket.py", line 808, in create_connection
    raise err
  File "/usr/lib/python3.8/socket.py", line 796, in create_connection
    sock.connect(sa)
ConnectionRefusedError: [Errno 111] Connection refused

During handling of the above exception, another exception occurred:

Traceback (most recent call last):
  File "apps/frappe/frappe/utils/scheduler.py", line 76, in enqueue_events_for_site
    if is_scheduler_inactive():
  File "apps/frappe/frappe/utils/scheduler.py", line 113, in is_scheduler_inactive
    if is_scheduler_disabled():
  File "apps/frappe/frappe/utils/scheduler.py", line 125, in is_scheduler_disabled
    frappe.db.get_single_value("System Settings", "enable_scheduler")
  File "apps/frappe/frappe/database/database.py", line 671, in get_single_value
    val = self.query.get_sql(
  File "apps/frappe/frappe/query_builder/utils.py", line 71, in execute_query
    return frappe.db.sql(query, params, *args, **kwargs)  # nosemgrep
  File "apps/frappe/frappe/database/database.py", line 145, in sql
    self.connect()
  File "apps/frappe/frappe/database/database.py", line 76, in connect
    self._conn = self.get_connection()
  File "apps/frappe/frappe/database/mariadb/database.py", line 78, in get_connection
    conn = pymysql.connect(
  File "env/lib/python3.8/site-packages/pymysql/connections.py", line 353, in __init__
    self.connect()
  File "env/lib/python3.8/site-packages/pymysql/connections.py", line 664, in connect
    raise exc
pymysql.err.OperationalError: (2003, "Can't connect to MySQL server on '127.0.0.1' ([Errno 111] Connection refused)")

2022-04-27 15:00:56,368 ERROR scheduler Exception in Enqueue Events for Site library.test
Traceback (most recent call last):
  File "env/lib/python3.8/site-packages/pymysql/connections.py", line 613, in connect
    sock = socket.create_connection(
  File "/usr/lib/python3.8/socket.py", line 808, in create_connection
    raise err
  File "/usr/lib/python3.8/socket.py", line 796, in create_connection
    sock.connect(sa)
ConnectionRefusedError: [Errno 111] Connection refused

During handling of the above exception, another exception occurred:

Traceback (most recent call last):
  File "apps/frappe/frappe/utils/scheduler.py", line 76, in enqueue_events_for_site
    if is_scheduler_inactive():
  File "apps/frappe/frappe/utils/scheduler.py", line 113, in is_scheduler_inactive
    if is_scheduler_disabled():
  File "apps/frappe/frappe/utils/scheduler.py", line 125, in is_scheduler_disabled
    frappe.db.get_single_value("System Settings", "enable_scheduler")
  File "apps/frappe/frappe/database/database.py", line 671, in get_single_value
    val = self.query.get_sql(
  File "apps/frappe/frappe/query_builder/utils.py", line 71, in execute_query
    return frappe.db.sql(query, params, *args, **kwargs)  # nosemgrep
  File "apps/frappe/frappe/database/database.py", line 145, in sql
    self.connect()
  File "apps/frappe/frappe/database/database.py", line 76, in connect
    self._conn = self.get_connection()
  File "apps/frappe/frappe/database/mariadb/database.py", line 78, in get_connection
    conn = pymysql.connect(
  File "env/lib/python3.8/site-packages/pymysql/connections.py", line 353, in __init__
    self.connect()
  File "env/lib/python3.8/site-packages/pymysql/connections.py", line 664, in connect
    raise exc
pymysql.err.OperationalError: (2003, "Can't connect to MySQL server on '127.0.0.1' ([Errno 111] Connection refused)")

2022-04-27 15:01:56,488 ERROR scheduler Exception in Enqueue Events for Site library.test
Traceback (most recent call last):
  File "env/lib/python3.8/site-packages/pymysql/connections.py", line 613, in connect
    sock = socket.create_connection(
  File "/usr/lib/python3.8/socket.py", line 808, in create_connection
    raise err
  File "/usr/lib/python3.8/socket.py", line 796, in create_connection
    sock.connect(sa)
ConnectionRefusedError: [Errno 111] Connection refused

During handling of the above exception, another exception occurred:

Traceback (most recent call last):
  File "apps/frappe/frappe/utils/scheduler.py", line 76, in enqueue_events_for_site
    if is_scheduler_inactive():
  File "apps/frappe/frappe/utils/scheduler.py", line 113, in is_scheduler_inactive
    if is_scheduler_disabled():
  File "apps/frappe/frappe/utils/scheduler.py", line 125, in is_scheduler_disabled
    frappe.db.get_single_value("System Settings", "enable_scheduler")
  File "apps/frappe/frappe/database/database.py", line 671, in get_single_value
    val = self.query.get_sql(
  File "apps/frappe/frappe/query_builder/utils.py", line 71, in execute_query
    return frappe.db.sql(query, params, *args, **kwargs)  # nosemgrep
  File "apps/frappe/frappe/database/database.py", line 145, in sql
    self.connect()
  File "apps/frappe/frappe/database/database.py", line 76, in connect
    self._conn = self.get_connection()
  File "apps/frappe/frappe/database/mariadb/database.py", line 78, in get_connection
    conn = pymysql.connect(
  File "env/lib/python3.8/site-packages/pymysql/connections.py", line 353, in __init__
    self.connect()
  File "env/lib/python3.8/site-packages/pymysql/connections.py", line 664, in connect
    raise exc
pymysql.err.OperationalError: (2003, "Can't connect to MySQL server on '127.0.0.1' ([Errno 111] Connection refused)")

2022-04-27 15:02:56,582 ERROR scheduler Exception in Enqueue Events for Site library.test
Traceback (most recent call last):
  File "apps/frappe/frappe/utils/scheduler.py", line 76, in enqueue_events_for_site
    if is_scheduler_inactive():
  File "apps/frappe/frappe/utils/scheduler.py", line 113, in is_scheduler_inactive
    if is_scheduler_disabled():
  File "apps/frappe/frappe/utils/scheduler.py", line 125, in is_scheduler_disabled
    frappe.db.get_single_value("System Settings", "enable_scheduler")
  File "apps/frappe/frappe/database/database.py", line 671, in get_single_value
    val = self.query.get_sql(
  File "apps/frappe/frappe/query_builder/utils.py", line 71, in execute_query
    return frappe.db.sql(query, params, *args, **kwargs)  # nosemgrep
  File "apps/frappe/frappe/database/database.py", line 145, in sql
    self.connect()
  File "apps/frappe/frappe/database/database.py", line 76, in connect
    self._conn = self.get_connection()
  File "apps/frappe/frappe/database/mariadb/database.py", line 78, in get_connection
    conn = pymysql.connect(
  File "env/lib/python3.8/site-packages/pymysql/connections.py", line 353, in __init__
    self.connect()
  File "env/lib/python3.8/site-packages/pymysql/connections.py", line 633, in connect
    self._request_authentication()
  File "env/lib/python3.8/site-packages/pymysql/connections.py", line 907, in _request_authentication
    auth_packet = self._read_packet()
  File "env/lib/python3.8/site-packages/pymysql/connections.py", line 725, in _read_packet
    packet.raise_for_error()
  File "env/lib/python3.8/site-packages/pymysql/protocol.py", line 221, in raise_for_error
    err.raise_mysql_exception(self._data)
  File "env/lib/python3.8/site-packages/pymysql/err.py", line 143, in raise_mysql_exception
    raise errorclass(errno, errval)
pymysql.err.OperationalError: (1698, "Access denied for user '_4b78d8359cb6244b'@'localhost'")

2022-04-27 15:03:56,674 ERROR scheduler Exception in Enqueue Events for Site library.test
Traceback (most recent call last):
  File "apps/frappe/frappe/utils/scheduler.py", line 76, in enqueue_events_for_site
    if is_scheduler_inactive():
  File "apps/frappe/frappe/utils/scheduler.py", line 113, in is_scheduler_inactive
    if is_scheduler_disabled():
  File "apps/frappe/frappe/utils/scheduler.py", line 125, in is_scheduler_disabled
    frappe.db.get_single_value("System Settings", "enable_scheduler")
  File "apps/frappe/frappe/database/database.py", line 671, in get_single_value
    val = self.query.get_sql(
  File "apps/frappe/frappe/query_builder/utils.py", line 71, in execute_query
    return frappe.db.sql(query, params, *args, **kwargs)  # nosemgrep
  File "apps/frappe/frappe/database/database.py", line 145, in sql
    self.connect()
  File "apps/frappe/frappe/database/database.py", line 76, in connect
    self._conn = self.get_connection()
  File "apps/frappe/frappe/database/mariadb/database.py", line 78, in get_connection
    conn = pymysql.connect(
  File "env/lib/python3.8/site-packages/pymysql/connections.py", line 353, in __init__
    self.connect()
  File "env/lib/python3.8/site-packages/pymysql/connections.py", line 633, in connect
    self._request_authentication()
  File "env/lib/python3.8/site-packages/pymysql/connections.py", line 907, in _request_authentication
    auth_packet = self._read_packet()
  File "env/lib/python3.8/site-packages/pymysql/connections.py", line 725, in _read_packet
    packet.raise_for_error()
  File "env/lib/python3.8/site-packages/pymysql/protocol.py", line 221, in raise_for_error
    err.raise_mysql_exception(self._data)
  File "env/lib/python3.8/site-packages/pymysql/err.py", line 143, in raise_mysql_exception
    raise errorclass(errno, errval)
pymysql.err.OperationalError: (1698, "Access denied for user '_4b78d8359cb6244b'@'localhost'")

2022-04-27 15:04:56,789 ERROR scheduler Exception in Enqueue Events for Site library.test
Traceback (most recent call last):
  File "apps/frappe/frappe/utils/scheduler.py", line 76, in enqueue_events_for_site
    if is_scheduler_inactive():
  File "apps/frappe/frappe/utils/scheduler.py", line 113, in is_scheduler_inactive
    if is_scheduler_disabled():
  File "apps/frappe/frappe/utils/scheduler.py", line 125, in is_scheduler_disabled
    frappe.db.get_single_value("System Settings", "enable_scheduler")
  File "apps/frappe/frappe/database/database.py", line 671, in get_single_value
    val = self.query.get_sql(
  File "apps/frappe/frappe/query_builder/utils.py", line 71, in execute_query
    return frappe.db.sql(query, params, *args, **kwargs)  # nosemgrep
  File "apps/frappe/frappe/database/database.py", line 145, in sql
    self.connect()
  File "apps/frappe/frappe/database/database.py", line 76, in connect
    self._conn = self.get_connection()
  File "apps/frappe/frappe/database/mariadb/database.py", line 78, in get_connection
    conn = pymysql.connect(
  File "env/lib/python3.8/site-packages/pymysql/connections.py", line 353, in __init__
    self.connect()
  File "env/lib/python3.8/site-packages/pymysql/connections.py", line 633, in connect
    self._request_authentication()
  File "env/lib/python3.8/site-packages/pymysql/connections.py", line 907, in _request_authentication
    auth_packet = self._read_packet()
  File "env/lib/python3.8/site-packages/pymysql/connections.py", line 725, in _read_packet
    packet.raise_for_error()
  File "env/lib/python3.8/site-packages/pymysql/protocol.py", line 221, in raise_for_error
    err.raise_mysql_exception(self._data)
  File "env/lib/python3.8/site-packages/pymysql/err.py", line 143, in raise_mysql_exception
    raise errorclass(errno, errval)
pymysql.err.OperationalError: (1698, "Access denied for user '_4b78d8359cb6244b'@'localhost'")

2022-04-27 15:05:56,896 ERROR scheduler Exception in Enqueue Events for Site library.test
Traceback (most recent call last):
  File "apps/frappe/frappe/utils/scheduler.py", line 76, in enqueue_events_for_site
    if is_scheduler_inactive():
  File "apps/frappe/frappe/utils/scheduler.py", line 113, in is_scheduler_inactive
    if is_scheduler_disabled():
  File "apps/frappe/frappe/utils/scheduler.py", line 125, in is_scheduler_disabled
    frappe.db.get_single_value("System Settings", "enable_scheduler")
  File "apps/frappe/frappe/database/database.py", line 671, in get_single_value
    val = self.query.get_sql(
  File "apps/frappe/frappe/query_builder/utils.py", line 71, in execute_query
    return frappe.db.sql(query, params, *args, **kwargs)  # nosemgrep
  File "apps/frappe/frappe/database/database.py", line 145, in sql
    self.connect()
  File "apps/frappe/frappe/database/database.py", line 76, in connect
    self._conn = self.get_connection()
  File "apps/frappe/frappe/database/mariadb/database.py", line 78, in get_connection
    conn = pymysql.connect(
  File "env/lib/python3.8/site-packages/pymysql/connections.py", line 353, in __init__
    self.connect()
  File "env/lib/python3.8/site-packages/pymysql/connections.py", line 633, in connect
    self._request_authentication()
  File "env/lib/python3.8/site-packages/pymysql/connections.py", line 907, in _request_authentication
    auth_packet = self._read_packet()
  File "env/lib/python3.8/site-packages/pymysql/connections.py", line 725, in _read_packet
    packet.raise_for_error()
  File "env/lib/python3.8/site-packages/pymysql/protocol.py", line 221, in raise_for_error
    err.raise_mysql_exception(self._data)
  File "env/lib/python3.8/site-packages/pymysql/err.py", line 143, in raise_mysql_exception
    raise errorclass(errno, errval)
pymysql.err.OperationalError: (1698, "Access denied for user '_4b78d8359cb6244b'@'localhost'")

2022-04-27 15:07:25,285 ERROR scheduler Exception in Enqueue Events for Site library.test
Traceback (most recent call last):
  File "apps/frappe/frappe/utils/scheduler.py", line 76, in enqueue_events_for_site
    if is_scheduler_inactive():
  File "apps/frappe/frappe/utils/scheduler.py", line 113, in is_scheduler_inactive
    if is_scheduler_disabled():
  File "apps/frappe/frappe/utils/scheduler.py", line 125, in is_scheduler_disabled
    frappe.db.get_single_value("System Settings", "enable_scheduler")
  File "apps/frappe/frappe/database/database.py", line 671, in get_single_value
    val = self.query.get_sql(
  File "apps/frappe/frappe/query_builder/utils.py", line 71, in execute_query
    return frappe.db.sql(query, params, *args, **kwargs)  # nosemgrep
  File "apps/frappe/frappe/database/database.py", line 145, in sql
    self.connect()
  File "apps/frappe/frappe/database/database.py", line 76, in connect
    self._conn = self.get_connection()
  File "apps/frappe/frappe/database/mariadb/database.py", line 78, in get_connection
    conn = pymysql.connect(
  File "env/lib/python3.8/site-packages/pymysql/connections.py", line 353, in __init__
    self.connect()
  File "env/lib/python3.8/site-packages/pymysql/connections.py", line 633, in connect
    self._request_authentication()
  File "env/lib/python3.8/site-packages/pymysql/connections.py", line 907, in _request_authentication
    auth_packet = self._read_packet()
  File "env/lib/python3.8/site-packages/pymysql/connections.py", line 725, in _read_packet
    packet.raise_for_error()
  File "env/lib/python3.8/site-packages/pymysql/protocol.py", line 221, in raise_for_error
    err.raise_mysql_exception(self._data)
  File "env/lib/python3.8/site-packages/pymysql/err.py", line 143, in raise_mysql_exception
    raise errorclass(errno, errval)
pymysql.err.OperationalError: (1698, "Access denied for user '_4b78d8359cb6244b'@'localhost'")

2022-04-27 15:07:25,288 ERROR scheduler Exception in Enqueue Events for Site pande.test
Traceback (most recent call last):
  File "apps/frappe/frappe/utils/scheduler.py", line 76, in enqueue_events_for_site
    if is_scheduler_inactive():
  File "apps/frappe/frappe/utils/scheduler.py", line 113, in is_scheduler_inactive
    if is_scheduler_disabled():
  File "apps/frappe/frappe/utils/scheduler.py", line 125, in is_scheduler_disabled
    frappe.db.get_single_value("System Settings", "enable_scheduler")
  File "apps/frappe/frappe/database/database.py", line 671, in get_single_value
    val = self.query.get_sql(
  File "apps/frappe/frappe/query_builder/utils.py", line 71, in execute_query
    return frappe.db.sql(query, params, *args, **kwargs)  # nosemgrep
  File "apps/frappe/frappe/database/database.py", line 145, in sql
    self.connect()
  File "apps/frappe/frappe/database/database.py", line 76, in connect
    self._conn = self.get_connection()
  File "apps/frappe/frappe/database/mariadb/database.py", line 78, in get_connection
    conn = pymysql.connect(
  File "env/lib/python3.8/site-packages/pymysql/connections.py", line 353, in __init__
    self.connect()
  File "env/lib/python3.8/site-packages/pymysql/connections.py", line 633, in connect
    self._request_authentication()
  File "env/lib/python3.8/site-packages/pymysql/connections.py", line 907, in _request_authentication
    auth_packet = self._read_packet()
  File "env/lib/python3.8/site-packages/pymysql/connections.py", line 725, in _read_packet
    packet.raise_for_error()
  File "env/lib/python3.8/site-packages/pymysql/protocol.py", line 221, in raise_for_error
    err.raise_mysql_exception(self._data)
  File "env/lib/python3.8/site-packages/pymysql/err.py", line 143, in raise_mysql_exception
    raise errorclass(errno, errval)
pymysql.err.OperationalError: (1698, "Access denied for user '_cec12ea57feb6be2'@'localhost'")

2022-04-27 15:07:25,291 ERROR scheduler Exception in Enqueue Events for Site upande.test
Traceback (most recent call last):
  File "apps/frappe/frappe/utils/scheduler.py", line 76, in enqueue_events_for_site
    if is_scheduler_inactive():
  File "apps/frappe/frappe/utils/scheduler.py", line 113, in is_scheduler_inactive
    if is_scheduler_disabled():
  File "apps/frappe/frappe/utils/scheduler.py", line 125, in is_scheduler_disabled
    frappe.db.get_single_value("System Settings", "enable_scheduler")
  File "apps/frappe/frappe/database/database.py", line 671, in get_single_value
    val = self.query.get_sql(
  File "apps/frappe/frappe/query_builder/utils.py", line 71, in execute_query
    return frappe.db.sql(query, params, *args, **kwargs)  # nosemgrep
  File "apps/frappe/frappe/database/database.py", line 145, in sql
    self.connect()
  File "apps/frappe/frappe/database/database.py", line 76, in connect
    self._conn = self.get_connection()
  File "apps/frappe/frappe/database/mariadb/database.py", line 78, in get_connection
    conn = pymysql.connect(
  File "env/lib/python3.8/site-packages/pymysql/connections.py", line 353, in __init__
    self.connect()
  File "env/lib/python3.8/site-packages/pymysql/connections.py", line 633, in connect
    self._request_authentication()
  File "env/lib/python3.8/site-packages/pymysql/connections.py", line 907, in _request_authentication
    auth_packet = self._read_packet()
  File "env/lib/python3.8/site-packages/pymysql/connections.py", line 725, in _read_packet
    packet.raise_for_error()
  File "env/lib/python3.8/site-packages/pymysql/protocol.py", line 221, in raise_for_error
    err.raise_mysql_exception(self._data)
  File "env/lib/python3.8/site-packages/pymysql/err.py", line 143, in raise_mysql_exception
    raise errorclass(errno, errval)
pymysql.err.OperationalError: (1698, "Access denied for user '_c713649fd2ca61f8'@'localhost'")

2022-04-27 15:07:25,294 ERROR scheduler Exception in Enqueue Events for Site yy.local
Traceback (most recent call last):
  File "apps/frappe/frappe/utils/scheduler.py", line 76, in enqueue_events_for_site
    if is_scheduler_inactive():
  File "apps/frappe/frappe/utils/scheduler.py", line 113, in is_scheduler_inactive
    if is_scheduler_disabled():
  File "apps/frappe/frappe/utils/scheduler.py", line 125, in is_scheduler_disabled
    frappe.db.get_single_value("System Settings", "enable_scheduler")
  File "apps/frappe/frappe/database/database.py", line 671, in get_single_value
    val = self.query.get_sql(
  File "apps/frappe/frappe/query_builder/utils.py", line 71, in execute_query
    return frappe.db.sql(query, params, *args, **kwargs)  # nosemgrep
  File "apps/frappe/frappe/database/database.py", line 145, in sql
    self.connect()
  File "apps/frappe/frappe/database/database.py", line 76, in connect
    self._conn = self.get_connection()
  File "apps/frappe/frappe/database/mariadb/database.py", line 78, in get_connection
    conn = pymysql.connect(
  File "env/lib/python3.8/site-packages/pymysql/connections.py", line 353, in __init__
    self.connect()
  File "env/lib/python3.8/site-packages/pymysql/connections.py", line 633, in connect
    self._request_authentication()
  File "env/lib/python3.8/site-packages/pymysql/connections.py", line 907, in _request_authentication
    auth_packet = self._read_packet()
  File "env/lib/python3.8/site-packages/pymysql/connections.py", line 725, in _read_packet
    packet.raise_for_error()
  File "env/lib/python3.8/site-packages/pymysql/protocol.py", line 221, in raise_for_error
    err.raise_mysql_exception(self._data)
  File "env/lib/python3.8/site-packages/pymysql/err.py", line 143, in raise_mysql_exception
    raise errorclass(errno, errval)
pymysql.err.OperationalError: (1698, "Access denied for user '_770670234724b2a9'@'localhost'")

2022-04-27 15:07:25,297 ERROR scheduler Exception in Enqueue Events for Site yy.test
Traceback (most recent call last):
  File "apps/frappe/frappe/utils/scheduler.py", line 76, in enqueue_events_for_site
    if is_scheduler_inactive():
  File "apps/frappe/frappe/utils/scheduler.py", line 113, in is_scheduler_inactive
    if is_scheduler_disabled():
  File "apps/frappe/frappe/utils/scheduler.py", line 125, in is_scheduler_disabled
    frappe.db.get_single_value("System Settings", "enable_scheduler")
  File "apps/frappe/frappe/database/database.py", line 671, in get_single_value
    val = self.query.get_sql(
  File "apps/frappe/frappe/query_builder/utils.py", line 71, in execute_query
    return frappe.db.sql(query, params, *args, **kwargs)  # nosemgrep
  File "apps/frappe/frappe/database/database.py", line 145, in sql
    self.connect()
  File "apps/frappe/frappe/database/database.py", line 76, in connect
    self._conn = self.get_connection()
  File "apps/frappe/frappe/database/mariadb/database.py", line 78, in get_connection
    conn = pymysql.connect(
  File "env/lib/python3.8/site-packages/pymysql/connections.py", line 353, in __init__
    self.connect()
  File "env/lib/python3.8/site-packages/pymysql/connections.py", line 633, in connect
    self._request_authentication()
  File "env/lib/python3.8/site-packages/pymysql/connections.py", line 907, in _request_authentication
    auth_packet = self._read_packet()
  File "env/lib/python3.8/site-packages/pymysql/connections.py", line 725, in _read_packet
    packet.raise_for_error()
  File "env/lib/python3.8/site-packages/pymysql/protocol.py", line 221, in raise_for_error
    err.raise_mysql_exception(self._data)
  File "env/lib/python3.8/site-packages/pymysql/err.py", line 143, in raise_mysql_exception
    raise errorclass(errno, errval)
pymysql.err.OperationalError: (1698, "Access denied for user '_9d814256ac226c5d'@'localhost'")

2022-04-27 15:08:25,385 ERROR scheduler Exception in Enqueue Events for Site library.test
Traceback (most recent call last):
  File "apps/frappe/frappe/utils/scheduler.py", line 76, in enqueue_events_for_site
    if is_scheduler_inactive():
  File "apps/frappe/frappe/utils/scheduler.py", line 113, in is_scheduler_inactive
    if is_scheduler_disabled():
  File "apps/frappe/frappe/utils/scheduler.py", line 125, in is_scheduler_disabled
    frappe.db.get_single_value("System Settings", "enable_scheduler")
  File "apps/frappe/frappe/database/database.py", line 671, in get_single_value
    val = self.query.get_sql(
  File "apps/frappe/frappe/query_builder/utils.py", line 71, in execute_query
    return frappe.db.sql(query, params, *args, **kwargs)  # nosemgrep
  File "apps/frappe/frappe/database/database.py", line 145, in sql
    self.connect()
  File "apps/frappe/frappe/database/database.py", line 76, in connect
    self._conn = self.get_connection()
  File "apps/frappe/frappe/database/mariadb/database.py", line 78, in get_connection
    conn = pymysql.connect(
  File "env/lib/python3.8/site-packages/pymysql/connections.py", line 353, in __init__
    self.connect()
  File "env/lib/python3.8/site-packages/pymysql/connections.py", line 633, in connect
    self._request_authentication()
  File "env/lib/python3.8/site-packages/pymysql/connections.py", line 907, in _request_authentication
    auth_packet = self._read_packet()
  File "env/lib/python3.8/site-packages/pymysql/connections.py", line 725, in _read_packet
    packet.raise_for_error()
  File "env/lib/python3.8/site-packages/pymysql/protocol.py", line 221, in raise_for_error
    err.raise_mysql_exception(self._data)
  File "env/lib/python3.8/site-packages/pymysql/err.py", line 143, in raise_mysql_exception
    raise errorclass(errno, errval)
pymysql.err.OperationalError: (1698, "Access denied for user '_4b78d8359cb6244b'@'localhost'")

2022-04-27 15:08:25,396 ERROR scheduler Exception in Enqueue Events for Site pande.test
Traceback (most recent call last):
  File "apps/frappe/frappe/utils/scheduler.py", line 76, in enqueue_events_for_site
    if is_scheduler_inactive():
  File "apps/frappe/frappe/utils/scheduler.py", line 113, in is_scheduler_inactive
    if is_scheduler_disabled():
  File "apps/frappe/frappe/utils/scheduler.py", line 125, in is_scheduler_disabled
    frappe.db.get_single_value("System Settings", "enable_scheduler")
  File "apps/frappe/frappe/database/database.py", line 671, in get_single_value
    val = self.query.get_sql(
  File "apps/frappe/frappe/query_builder/utils.py", line 71, in execute_query
    return frappe.db.sql(query, params, *args, **kwargs)  # nosemgrep
  File "apps/frappe/frappe/database/database.py", line 145, in sql
    self.connect()
  File "apps/frappe/frappe/database/database.py", line 76, in connect
    self._conn = self.get_connection()
  File "apps/frappe/frappe/database/mariadb/database.py", line 78, in get_connection
    conn = pymysql.connect(
  File "env/lib/python3.8/site-packages/pymysql/connections.py", line 353, in __init__
    self.connect()
  File "env/lib/python3.8/site-packages/pymysql/connections.py", line 633, in connect
    self._request_authentication()
  File "env/lib/python3.8/site-packages/pymysql/connections.py", line 907, in _request_authentication
    auth_packet = self._read_packet()
  File "env/lib/python3.8/site-packages/pymysql/connections.py", line 725, in _read_packet
    packet.raise_for_error()
  File "env/lib/python3.8/site-packages/pymysql/protocol.py", line 221, in raise_for_error
    err.raise_mysql_exception(self._data)
  File "env/lib/python3.8/site-packages/pymysql/err.py", line 143, in raise_mysql_exception
    raise errorclass(errno, errval)
pymysql.err.OperationalError: (1698, "Access denied for user '_cec12ea57feb6be2'@'localhost'")

2022-04-27 15:08:25,402 ERROR scheduler Exception in Enqueue Events for Site pass.test
Traceback (most recent call last):
  File "apps/frappe/frappe/utils/scheduler.py", line 76, in enqueue_events_for_site
    if is_scheduler_inactive():
  File "apps/frappe/frappe/utils/scheduler.py", line 113, in is_scheduler_inactive
    if is_scheduler_disabled():
  File "apps/frappe/frappe/utils/scheduler.py", line 125, in is_scheduler_disabled
    frappe.db.get_single_value("System Settings", "enable_scheduler")
  File "apps/frappe/frappe/database/database.py", line 671, in get_single_value
    val = self.query.get_sql(
  File "apps/frappe/frappe/query_builder/utils.py", line 71, in execute_query
    return frappe.db.sql(query, params, *args, **kwargs)  # nosemgrep
  File "apps/frappe/frappe/database/database.py", line 145, in sql
    self.connect()
  File "apps/frappe/frappe/database/database.py", line 76, in connect
    self._conn = self.get_connection()
  File "apps/frappe/frappe/database/mariadb/database.py", line 78, in get_connection
    conn = pymysql.connect(
  File "env/lib/python3.8/site-packages/pymysql/connections.py", line 353, in __init__
    self.connect()
  File "env/lib/python3.8/site-packages/pymysql/connections.py", line 633, in connect
    self._request_authentication()
  File "env/lib/python3.8/site-packages/pymysql/connections.py", line 907, in _request_authentication
    auth_packet = self._read_packet()
  File "env/lib/python3.8/site-packages/pymysql/connections.py", line 725, in _read_packet
    packet.raise_for_error()
  File "env/lib/python3.8/site-packages/pymysql/protocol.py", line 221, in raise_for_error
    err.raise_mysql_exception(self._data)
  File "env/lib/python3.8/site-packages/pymysql/err.py", line 143, in raise_mysql_exception
    raise errorclass(errno, errval)
pymysql.err.OperationalError: (1698, "Access denied for user '_75118da431c451ca'@'localhost'")

2022-04-27 15:08:25,407 ERROR scheduler Exception in Enqueue Events for Site upande.test
Traceback (most recent call last):
  File "apps/frappe/frappe/utils/scheduler.py", line 76, in enqueue_events_for_site
    if is_scheduler_inactive():
  File "apps/frappe/frappe/utils/scheduler.py", line 113, in is_scheduler_inactive
    if is_scheduler_disabled():
  File "apps/frappe/frappe/utils/scheduler.py", line 125, in is_scheduler_disabled
    frappe.db.get_single_value("System Settings", "enable_scheduler")
  File "apps/frappe/frappe/database/database.py", line 671, in get_single_value
    val = self.query.get_sql(
  File "apps/frappe/frappe/query_builder/utils.py", line 71, in execute_query
    return frappe.db.sql(query, params, *args, **kwargs)  # nosemgrep
  File "apps/frappe/frappe/database/database.py", line 145, in sql
    self.connect()
  File "apps/frappe/frappe/database/database.py", line 76, in connect
    self._conn = self.get_connection()
  File "apps/frappe/frappe/database/mariadb/database.py", line 78, in get_connection
    conn = pymysql.connect(
  File "env/lib/python3.8/site-packages/pymysql/connections.py", line 353, in __init__
    self.connect()
  File "env/lib/python3.8/site-packages/pymysql/connections.py", line 633, in connect
    self._request_authentication()
  File "env/lib/python3.8/site-packages/pymysql/connections.py", line 907, in _request_authentication
    auth_packet = self._read_packet()
  File "env/lib/python3.8/site-packages/pymysql/connections.py", line 725, in _read_packet
    packet.raise_for_error()
  File "env/lib/python3.8/site-packages/pymysql/protocol.py", line 221, in raise_for_error
    err.raise_mysql_exception(self._data)
  File "env/lib/python3.8/site-packages/pymysql/err.py", line 143, in raise_mysql_exception
    raise errorclass(errno, errval)
pymysql.err.OperationalError: (1698, "Access denied for user '_c713649fd2ca61f8'@'localhost'")

2022-04-27 15:08:25,411 ERROR scheduler Exception in Enqueue Events for Site yy.local
Traceback (most recent call last):
  File "apps/frappe/frappe/utils/scheduler.py", line 76, in enqueue_events_for_site
    if is_scheduler_inactive():
  File "apps/frappe/frappe/utils/scheduler.py", line 113, in is_scheduler_inactive
    if is_scheduler_disabled():
  File "apps/frappe/frappe/utils/scheduler.py", line 125, in is_scheduler_disabled
    frappe.db.get_single_value("System Settings", "enable_scheduler")
  File "apps/frappe/frappe/database/database.py", line 671, in get_single_value
    val = self.query.get_sql(
  File "apps/frappe/frappe/query_builder/utils.py", line 71, in execute_query
    return frappe.db.sql(query, params, *args, **kwargs)  # nosemgrep
  File "apps/frappe/frappe/database/database.py", line 145, in sql
    self.connect()
  File "apps/frappe/frappe/database/database.py", line 76, in connect
    self._conn = self.get_connection()
  File "apps/frappe/frappe/database/mariadb/database.py", line 78, in get_connection
    conn = pymysql.connect(
  File "env/lib/python3.8/site-packages/pymysql/connections.py", line 353, in __init__
    self.connect()
  File "env/lib/python3.8/site-packages/pymysql/connections.py", line 633, in connect
    self._request_authentication()
  File "env/lib/python3.8/site-packages/pymysql/connections.py", line 907, in _request_authentication
    auth_packet = self._read_packet()
  File "env/lib/python3.8/site-packages/pymysql/connections.py", line 725, in _read_packet
    packet.raise_for_error()
  File "env/lib/python3.8/site-packages/pymysql/protocol.py", line 221, in raise_for_error
    err.raise_mysql_exception(self._data)
  File "env/lib/python3.8/site-packages/pymysql/err.py", line 143, in raise_mysql_exception
    raise errorclass(errno, errval)
pymysql.err.OperationalError: (1698, "Access denied for user '_770670234724b2a9'@'localhost'")

2022-04-27 15:08:25,414 ERROR scheduler Exception in Enqueue Events for Site yy.test
Traceback (most recent call last):
  File "apps/frappe/frappe/utils/scheduler.py", line 76, in enqueue_events_for_site
    if is_scheduler_inactive():
  File "apps/frappe/frappe/utils/scheduler.py", line 113, in is_scheduler_inactive
    if is_scheduler_disabled():
  File "apps/frappe/frappe/utils/scheduler.py", line 125, in is_scheduler_disabled
    frappe.db.get_single_value("System Settings", "enable_scheduler")
  File "apps/frappe/frappe/database/database.py", line 671, in get_single_value
    val = self.query.get_sql(
  File "apps/frappe/frappe/query_builder/utils.py", line 71, in execute_query
    return frappe.db.sql(query, params, *args, **kwargs)  # nosemgrep
  File "apps/frappe/frappe/database/database.py", line 145, in sql
    self.connect()
  File "apps/frappe/frappe/database/database.py", line 76, in connect
    self._conn = self.get_connection()
  File "apps/frappe/frappe/database/mariadb/database.py", line 78, in get_connection
    conn = pymysql.connect(
  File "env/lib/python3.8/site-packages/pymysql/connections.py", line 353, in __init__
    self.connect()
  File "env/lib/python3.8/site-packages/pymysql/connections.py", line 633, in connect
    self._request_authentication()
  File "env/lib/python3.8/site-packages/pymysql/connections.py", line 907, in _request_authentication
    auth_packet = self._read_packet()
  File "env/lib/python3.8/site-packages/pymysql/connections.py", line 725, in _read_packet
    packet.raise_for_error()
  File "env/lib/python3.8/site-packages/pymysql/protocol.py", line 221, in raise_for_error
    err.raise_mysql_exception(self._data)
  File "env/lib/python3.8/site-packages/pymysql/err.py", line 143, in raise_mysql_exception
    raise errorclass(errno, errval)
pymysql.err.OperationalError: (1698, "Access denied for user '_9d814256ac226c5d'@'localhost'")

2022-04-27 15:09:25,504 ERROR scheduler Exception in Enqueue Events for Site library.test
Traceback (most recent call last):
  File "apps/frappe/frappe/utils/scheduler.py", line 76, in enqueue_events_for_site
    if is_scheduler_inactive():
  File "apps/frappe/frappe/utils/scheduler.py", line 113, in is_scheduler_inactive
    if is_scheduler_disabled():
  File "apps/frappe/frappe/utils/scheduler.py", line 125, in is_scheduler_disabled
    frappe.db.get_single_value("System Settings", "enable_scheduler")
  File "apps/frappe/frappe/database/database.py", line 671, in get_single_value
    val = self.query.get_sql(
  File "apps/frappe/frappe/query_builder/utils.py", line 71, in execute_query
    return frappe.db.sql(query, params, *args, **kwargs)  # nosemgrep
  File "apps/frappe/frappe/database/database.py", line 145, in sql
    self.connect()
  File "apps/frappe/frappe/database/database.py", line 76, in connect
    self._conn = self.get_connection()
  File "apps/frappe/frappe/database/mariadb/database.py", line 78, in get_connection
    conn = pymysql.connect(
  File "env/lib/python3.8/site-packages/pymysql/connections.py", line 353, in __init__
    self.connect()
  File "env/lib/python3.8/site-packages/pymysql/connections.py", line 633, in connect
    self._request_authentication()
  File "env/lib/python3.8/site-packages/pymysql/connections.py", line 907, in _request_authentication
    auth_packet = self._read_packet()
  File "env/lib/python3.8/site-packages/pymysql/connections.py", line 725, in _read_packet
    packet.raise_for_error()
  File "env/lib/python3.8/site-packages/pymysql/protocol.py", line 221, in raise_for_error
    err.raise_mysql_exception(self._data)
  File "env/lib/python3.8/site-packages/pymysql/err.py", line 143, in raise_mysql_exception
    raise errorclass(errno, errval)
pymysql.err.OperationalError: (1698, "Access denied for user '_4b78d8359cb6244b'@'localhost'")

2022-04-27 15:09:25,512 ERROR scheduler Exception in Enqueue Events for Site pande.test
Traceback (most recent call last):
  File "apps/frappe/frappe/utils/scheduler.py", line 76, in enqueue_events_for_site
    if is_scheduler_inactive():
  File "apps/frappe/frappe/utils/scheduler.py", line 113, in is_scheduler_inactive
    if is_scheduler_disabled():
  File "apps/frappe/frappe/utils/scheduler.py", line 125, in is_scheduler_disabled
    frappe.db.get_single_value("System Settings", "enable_scheduler")
  File "apps/frappe/frappe/database/database.py", line 671, in get_single_value
    val = self.query.get_sql(
  File "apps/frappe/frappe/query_builder/utils.py", line 71, in execute_query
    return frappe.db.sql(query, params, *args, **kwargs)  # nosemgrep
  File "apps/frappe/frappe/database/database.py", line 145, in sql
    self.connect()
  File "apps/frappe/frappe/database/database.py", line 76, in connect
    self._conn = self.get_connection()
  File "apps/frappe/frappe/database/mariadb/database.py", line 78, in get_connection
    conn = pymysql.connect(
  File "env/lib/python3.8/site-packages/pymysql/connections.py", line 353, in __init__
    self.connect()
  File "env/lib/python3.8/site-packages/pymysql/connections.py", line 633, in connect
    self._request_authentication()
  File "env/lib/python3.8/site-packages/pymysql/connections.py", line 907, in _request_authentication
    auth_packet = self._read_packet()
  File "env/lib/python3.8/site-packages/pymysql/connections.py", line 725, in _read_packet
    packet.raise_for_error()
  File "env/lib/python3.8/site-packages/pymysql/protocol.py", line 221, in raise_for_error
    err.raise_mysql_exception(self._data)
  File "env/lib/python3.8/site-packages/pymysql/err.py", line 143, in raise_mysql_exception
    raise errorclass(errno, errval)
pymysql.err.OperationalError: (1698, "Access denied for user '_cec12ea57feb6be2'@'localhost'")

2022-04-27 15:09:25,522 ERROR scheduler Exception in Enqueue Events for Site pass.test
Traceback (most recent call last):
  File "apps/frappe/frappe/utils/scheduler.py", line 76, in enqueue_events_for_site
    if is_scheduler_inactive():
  File "apps/frappe/frappe/utils/scheduler.py", line 113, in is_scheduler_inactive
    if is_scheduler_disabled():
  File "apps/frappe/frappe/utils/scheduler.py", line 125, in is_scheduler_disabled
    frappe.db.get_single_value("System Settings", "enable_scheduler")
  File "apps/frappe/frappe/database/database.py", line 671, in get_single_value
    val = self.query.get_sql(
  File "apps/frappe/frappe/query_builder/utils.py", line 71, in execute_query
    return frappe.db.sql(query, params, *args, **kwargs)  # nosemgrep
  File "apps/frappe/frappe/database/database.py", line 145, in sql
    self.connect()
  File "apps/frappe/frappe/database/database.py", line 76, in connect
    self._conn = self.get_connection()
  File "apps/frappe/frappe/database/mariadb/database.py", line 78, in get_connection
    conn = pymysql.connect(
  File "env/lib/python3.8/site-packages/pymysql/connections.py", line 353, in __init__
    self.connect()
  File "env/lib/python3.8/site-packages/pymysql/connections.py", line 633, in connect
    self._request_authentication()
  File "env/lib/python3.8/site-packages/pymysql/connections.py", line 907, in _request_authentication
    auth_packet = self._read_packet()
  File "env/lib/python3.8/site-packages/pymysql/connections.py", line 725, in _read_packet
    packet.raise_for_error()
  File "env/lib/python3.8/site-packages/pymysql/protocol.py", line 221, in raise_for_error
    err.raise_mysql_exception(self._data)
  File "env/lib/python3.8/site-packages/pymysql/err.py", line 143, in raise_mysql_exception
    raise errorclass(errno, errval)
pymysql.err.OperationalError: (1698, "Access denied for user '_75118da431c451ca'@'localhost'")

2022-04-27 15:09:25,527 ERROR scheduler Exception in Enqueue Events for Site upande.test
Traceback (most recent call last):
  File "apps/frappe/frappe/utils/scheduler.py", line 76, in enqueue_events_for_site
    if is_scheduler_inactive():
  File "apps/frappe/frappe/utils/scheduler.py", line 113, in is_scheduler_inactive
    if is_scheduler_disabled():
  File "apps/frappe/frappe/utils/scheduler.py", line 125, in is_scheduler_disabled
    frappe.db.get_single_value("System Settings", "enable_scheduler")
  File "apps/frappe/frappe/database/database.py", line 671, in get_single_value
    val = self.query.get_sql(
  File "apps/frappe/frappe/query_builder/utils.py", line 71, in execute_query
    return frappe.db.sql(query, params, *args, **kwargs)  # nosemgrep
  File "apps/frappe/frappe/database/database.py", line 145, in sql
    self.connect()
  File "apps/frappe/frappe/database/database.py", line 76, in connect
    self._conn = self.get_connection()
  File "apps/frappe/frappe/database/mariadb/database.py", line 78, in get_connection
    conn = pymysql.connect(
  File "env/lib/python3.8/site-packages/pymysql/connections.py", line 353, in __init__
    self.connect()
  File "env/lib/python3.8/site-packages/pymysql/connections.py", line 633, in connect
    self._request_authentication()
  File "env/lib/python3.8/site-packages/pymysql/connections.py", line 907, in _request_authentication
    auth_packet = self._read_packet()
  File "env/lib/python3.8/site-packages/pymysql/connections.py", line 725, in _read_packet
    packet.raise_for_error()
  File "env/lib/python3.8/site-packages/pymysql/protocol.py", line 221, in raise_for_error
    err.raise_mysql_exception(self._data)
  File "env/lib/python3.8/site-packages/pymysql/err.py", line 143, in raise_mysql_exception
    raise errorclass(errno, errval)
pymysql.err.OperationalError: (1698, "Access denied for user '_c713649fd2ca61f8'@'localhost'")

2022-04-27 15:09:25,531 ERROR scheduler Exception in Enqueue Events for Site yy.local
Traceback (most recent call last):
  File "apps/frappe/frappe/utils/scheduler.py", line 76, in enqueue_events_for_site
    if is_scheduler_inactive():
  File "apps/frappe/frappe/utils/scheduler.py", line 113, in is_scheduler_inactive
    if is_scheduler_disabled():
  File "apps/frappe/frappe/utils/scheduler.py", line 125, in is_scheduler_disabled
    frappe.db.get_single_value("System Settings", "enable_scheduler")
  File "apps/frappe/frappe/database/database.py", line 671, in get_single_value
    val = self.query.get_sql(
  File "apps/frappe/frappe/query_builder/utils.py", line 71, in execute_query
    return frappe.db.sql(query, params, *args, **kwargs)  # nosemgrep
  File "apps/frappe/frappe/database/database.py", line 145, in sql
    self.connect()
  File "apps/frappe/frappe/database/database.py", line 76, in connect
    self._conn = self.get_connection()
  File "apps/frappe/frappe/database/mariadb/database.py", line 78, in get_connection
    conn = pymysql.connect(
  File "env/lib/python3.8/site-packages/pymysql/connections.py", line 353, in __init__
    self.connect()
  File "env/lib/python3.8/site-packages/pymysql/connections.py", line 633, in connect
    self._request_authentication()
  File "env/lib/python3.8/site-packages/pymysql/connections.py", line 907, in _request_authentication
    auth_packet = self._read_packet()
  File "env/lib/python3.8/site-packages/pymysql/connections.py", line 725, in _read_packet
    packet.raise_for_error()
  File "env/lib/python3.8/site-packages/pymysql/protocol.py", line 221, in raise_for_error
    err.raise_mysql_exception(self._data)
  File "env/lib/python3.8/site-packages/pymysql/err.py", line 143, in raise_mysql_exception
    raise errorclass(errno, errval)
pymysql.err.OperationalError: (1698, "Access denied for user '_770670234724b2a9'@'localhost'")

2022-04-27 15:09:25,534 ERROR scheduler Exception in Enqueue Events for Site yy.test
Traceback (most recent call last):
  File "apps/frappe/frappe/utils/scheduler.py", line 76, in enqueue_events_for_site
    if is_scheduler_inactive():
  File "apps/frappe/frappe/utils/scheduler.py", line 113, in is_scheduler_inactive
    if is_scheduler_disabled():
  File "apps/frappe/frappe/utils/scheduler.py", line 125, in is_scheduler_disabled
    frappe.db.get_single_value("System Settings", "enable_scheduler")
  File "apps/frappe/frappe/database/database.py", line 671, in get_single_value
    val = self.query.get_sql(
  File "apps/frappe/frappe/query_builder/utils.py", line 71, in execute_query
    return frappe.db.sql(query, params, *args, **kwargs)  # nosemgrep
  File "apps/frappe/frappe/database/database.py", line 145, in sql
    self.connect()
  File "apps/frappe/frappe/database/database.py", line 76, in connect
    self._conn = self.get_connection()
  File "apps/frappe/frappe/database/mariadb/database.py", line 78, in get_connection
    conn = pymysql.connect(
  File "env/lib/python3.8/site-packages/pymysql/connections.py", line 353, in __init__
    self.connect()
  File "env/lib/python3.8/site-packages/pymysql/connections.py", line 633, in connect
    self._request_authentication()
  File "env/lib/python3.8/site-packages/pymysql/connections.py", line 907, in _request_authentication
    auth_packet = self._read_packet()
  File "env/lib/python3.8/site-packages/pymysql/connections.py", line 725, in _read_packet
    packet.raise_for_error()
  File "env/lib/python3.8/site-packages/pymysql/protocol.py", line 221, in raise_for_error
    err.raise_mysql_exception(self._data)
  File "env/lib/python3.8/site-packages/pymysql/err.py", line 143, in raise_mysql_exception
    raise errorclass(errno, errval)
pymysql.err.OperationalError: (1698, "Access denied for user '_9d814256ac226c5d'@'localhost'")

