2022-04-27 14:29:52,759 ERROR scheduler Exception in Enqueue Events for Site yy.local
Traceback (most recent call last):
  File "env/lib/python3.8/site-packages/pymysql/connections.py", line 613, in connect
    sock = socket.create_connection(
  File "/usr/lib/python3.8/socket.py", line 808, in create_connection
    raise err
  File "/usr/lib/python3.8/socket.py", line 796, in create_connection
    sock.connect(sa)
ConnectionRefusedError: [Errno 111] Connection refused

During handling of the above exception, another exception occurred:

Traceback (most recent call last):
  File "apps/frappe/frappe/utils/scheduler.py", line 76, in enqueue_events_for_site
    if is_scheduler_inactive():
  File "apps/frappe/frappe/utils/scheduler.py", line 113, in is_scheduler_inactive
    if is_scheduler_disabled():
  File "apps/frappe/frappe/utils/scheduler.py", line 125, in is_scheduler_disabled
    frappe.db.get_single_value("System Settings", "enable_scheduler")
  File "apps/frappe/frappe/database/database.py", line 671, in get_single_value
    val = self.query.get_sql(
  File "apps/frappe/frappe/query_builder/utils.py", line 71, in execute_query
    return frappe.db.sql(query, params, *args, **kwargs)  # nosemgrep
  File "apps/frappe/frappe/database/database.py", line 145, in sql
    self.connect()
  File "apps/frappe/frappe/database/database.py", line 76, in connect
    self._conn = self.get_connection()
  File "apps/frappe/frappe/database/mariadb/database.py", line 78, in get_connection
    conn = pymysql.connect(
  File "env/lib/python3.8/site-packages/pymysql/connections.py", line 353, in __init__
    self.connect()
  File "env/lib/python3.8/site-packages/pymysql/connections.py", line 664, in connect
    raise exc
pymysql.err.OperationalError: (2003, "Can't connect to MySQL server on '127.0.0.1' ([Errno 111] Connection refused)")

2022-04-27 14:30:52,924 ERROR scheduler Exception in Enqueue Events for Site yy.local
Traceback (most recent call last):
  File "env/lib/python3.8/site-packages/pymysql/connections.py", line 613, in connect
    sock = socket.create_connection(
  File "/usr/lib/python3.8/socket.py", line 808, in create_connection
    raise err
  File "/usr/lib/python3.8/socket.py", line 796, in create_connection
    sock.connect(sa)
ConnectionRefusedError: [Errno 111] Connection refused

During handling of the above exception, another exception occurred:

Traceback (most recent call last):
  File "apps/frappe/frappe/utils/scheduler.py", line 76, in enqueue_events_for_site
    if is_scheduler_inactive():
  File "apps/frappe/frappe/utils/scheduler.py", line 113, in is_scheduler_inactive
    if is_scheduler_disabled():
  File "apps/frappe/frappe/utils/scheduler.py", line 125, in is_scheduler_disabled
    frappe.db.get_single_value("System Settings", "enable_scheduler")
  File "apps/frappe/frappe/database/database.py", line 671, in get_single_value
    val = self.query.get_sql(
  File "apps/frappe/frappe/query_builder/utils.py", line 71, in execute_query
    return frappe.db.sql(query, params, *args, **kwargs)  # nosemgrep
  File "apps/frappe/frappe/database/database.py", line 145, in sql
    self.connect()
  File "apps/frappe/frappe/database/database.py", line 76, in connect
    self._conn = self.get_connection()
  File "apps/frappe/frappe/database/mariadb/database.py", line 78, in get_connection
    conn = pymysql.connect(
  File "env/lib/python3.8/site-packages/pymysql/connections.py", line 353, in __init__
    self.connect()
  File "env/lib/python3.8/site-packages/pymysql/connections.py", line 664, in connect
    raise exc
pymysql.err.OperationalError: (2003, "Can't connect to MySQL server on '127.0.0.1' ([Errno 111] Connection refused)")

2022-04-27 14:31:53,021 ERROR scheduler Exception in Enqueue Events for Site yy.local
Traceback (most recent call last):
  File "env/lib/python3.8/site-packages/pymysql/connections.py", line 613, in connect
    sock = socket.create_connection(
  File "/usr/lib/python3.8/socket.py", line 808, in create_connection
    raise err
  File "/usr/lib/python3.8/socket.py", line 796, in create_connection
    sock.connect(sa)
ConnectionRefusedError: [Errno 111] Connection refused

During handling of the above exception, another exception occurred:

Traceback (most recent call last):
  File "apps/frappe/frappe/utils/scheduler.py", line 76, in enqueue_events_for_site
    if is_scheduler_inactive():
  File "apps/frappe/frappe/utils/scheduler.py", line 113, in is_scheduler_inactive
    if is_scheduler_disabled():
  File "apps/frappe/frappe/utils/scheduler.py", line 125, in is_scheduler_disabled
    frappe.db.get_single_value("System Settings", "enable_scheduler")
  File "apps/frappe/frappe/database/database.py", line 671, in get_single_value
    val = self.query.get_sql(
  File "apps/frappe/frappe/query_builder/utils.py", line 71, in execute_query
    return frappe.db.sql(query, params, *args, **kwargs)  # nosemgrep
  File "apps/frappe/frappe/database/database.py", line 145, in sql
    self.connect()
  File "apps/frappe/frappe/database/database.py", line 76, in connect
    self._conn = self.get_connection()
  File "apps/frappe/frappe/database/mariadb/database.py", line 78, in get_connection
    conn = pymysql.connect(
  File "env/lib/python3.8/site-packages/pymysql/connections.py", line 353, in __init__
    self.connect()
  File "env/lib/python3.8/site-packages/pymysql/connections.py", line 664, in connect
    raise exc
pymysql.err.OperationalError: (2003, "Can't connect to MySQL server on '127.0.0.1' ([Errno 111] Connection refused)")

2022-04-27 14:32:53,125 ERROR scheduler Exception in Enqueue Events for Site yy.local
Traceback (most recent call last):
  File "env/lib/python3.8/site-packages/pymysql/connections.py", line 613, in connect
    sock = socket.create_connection(
  File "/usr/lib/python3.8/socket.py", line 808, in create_connection
    raise err
  File "/usr/lib/python3.8/socket.py", line 796, in create_connection
    sock.connect(sa)
ConnectionRefusedError: [Errno 111] Connection refused

During handling of the above exception, another exception occurred:

Traceback (most recent call last):
  File "apps/frappe/frappe/utils/scheduler.py", line 76, in enqueue_events_for_site
    if is_scheduler_inactive():
  File "apps/frappe/frappe/utils/scheduler.py", line 113, in is_scheduler_inactive
    if is_scheduler_disabled():
  File "apps/frappe/frappe/utils/scheduler.py", line 125, in is_scheduler_disabled
    frappe.db.get_single_value("System Settings", "enable_scheduler")
  File "apps/frappe/frappe/database/database.py", line 671, in get_single_value
    val = self.query.get_sql(
  File "apps/frappe/frappe/query_builder/utils.py", line 71, in execute_query
    return frappe.db.sql(query, params, *args, **kwargs)  # nosemgrep
  File "apps/frappe/frappe/database/database.py", line 145, in sql
    self.connect()
  File "apps/frappe/frappe/database/database.py", line 76, in connect
    self._conn = self.get_connection()
  File "apps/frappe/frappe/database/mariadb/database.py", line 78, in get_connection
    conn = pymysql.connect(
  File "env/lib/python3.8/site-packages/pymysql/connections.py", line 353, in __init__
    self.connect()
  File "env/lib/python3.8/site-packages/pymysql/connections.py", line 664, in connect
    raise exc
pymysql.err.OperationalError: (2003, "Can't connect to MySQL server on '127.0.0.1' ([Errno 111] Connection refused)")

2022-04-27 14:33:53,205 ERROR scheduler Exception in Enqueue Events for Site yy.local
Traceback (most recent call last):
  File "env/lib/python3.8/site-packages/pymysql/connections.py", line 613, in connect
    sock = socket.create_connection(
  File "/usr/lib/python3.8/socket.py", line 808, in create_connection
    raise err
  File "/usr/lib/python3.8/socket.py", line 796, in create_connection
    sock.connect(sa)
ConnectionRefusedError: [Errno 111] Connection refused

During handling of the above exception, another exception occurred:

Traceback (most recent call last):
  File "apps/frappe/frappe/utils/scheduler.py", line 76, in enqueue_events_for_site
    if is_scheduler_inactive():
  File "apps/frappe/frappe/utils/scheduler.py", line 113, in is_scheduler_inactive
    if is_scheduler_disabled():
  File "apps/frappe/frappe/utils/scheduler.py", line 125, in is_scheduler_disabled
    frappe.db.get_single_value("System Settings", "enable_scheduler")
  File "apps/frappe/frappe/database/database.py", line 671, in get_single_value
    val = self.query.get_sql(
  File "apps/frappe/frappe/query_builder/utils.py", line 71, in execute_query
    return frappe.db.sql(query, params, *args, **kwargs)  # nosemgrep
  File "apps/frappe/frappe/database/database.py", line 145, in sql
    self.connect()
  File "apps/frappe/frappe/database/database.py", line 76, in connect
    self._conn = self.get_connection()
  File "apps/frappe/frappe/database/mariadb/database.py", line 78, in get_connection
    conn = pymysql.connect(
  File "env/lib/python3.8/site-packages/pymysql/connections.py", line 353, in __init__
    self.connect()
  File "env/lib/python3.8/site-packages/pymysql/connections.py", line 664, in connect
    raise exc
pymysql.err.OperationalError: (2003, "Can't connect to MySQL server on '127.0.0.1' ([Errno 111] Connection refused)")

2022-04-27 14:34:53,306 ERROR scheduler Exception in Enqueue Events for Site yy.local
Traceback (most recent call last):
  File "env/lib/python3.8/site-packages/pymysql/connections.py", line 613, in connect
    sock = socket.create_connection(
  File "/usr/lib/python3.8/socket.py", line 808, in create_connection
    raise err
  File "/usr/lib/python3.8/socket.py", line 796, in create_connection
    sock.connect(sa)
ConnectionRefusedError: [Errno 111] Connection refused

During handling of the above exception, another exception occurred:

Traceback (most recent call last):
  File "apps/frappe/frappe/utils/scheduler.py", line 76, in enqueue_events_for_site
    if is_scheduler_inactive():
  File "apps/frappe/frappe/utils/scheduler.py", line 113, in is_scheduler_inactive
    if is_scheduler_disabled():
  File "apps/frappe/frappe/utils/scheduler.py", line 125, in is_scheduler_disabled
    frappe.db.get_single_value("System Settings", "enable_scheduler")
  File "apps/frappe/frappe/database/database.py", line 671, in get_single_value
    val = self.query.get_sql(
  File "apps/frappe/frappe/query_builder/utils.py", line 71, in execute_query
    return frappe.db.sql(query, params, *args, **kwargs)  # nosemgrep
  File "apps/frappe/frappe/database/database.py", line 145, in sql
    self.connect()
  File "apps/frappe/frappe/database/database.py", line 76, in connect
    self._conn = self.get_connection()
  File "apps/frappe/frappe/database/mariadb/database.py", line 78, in get_connection
    conn = pymysql.connect(
  File "env/lib/python3.8/site-packages/pymysql/connections.py", line 353, in __init__
    self.connect()
  File "env/lib/python3.8/site-packages/pymysql/connections.py", line 664, in connect
    raise exc
pymysql.err.OperationalError: (2003, "Can't connect to MySQL server on '127.0.0.1' ([Errno 111] Connection refused)")

2022-04-27 14:35:53,450 ERROR scheduler Exception in Enqueue Events for Site yy.local
Traceback (most recent call last):
  File "env/lib/python3.8/site-packages/pymysql/connections.py", line 613, in connect
    sock = socket.create_connection(
  File "/usr/lib/python3.8/socket.py", line 808, in create_connection
    raise err
  File "/usr/lib/python3.8/socket.py", line 796, in create_connection
    sock.connect(sa)
ConnectionRefusedError: [Errno 111] Connection refused

During handling of the above exception, another exception occurred:

Traceback (most recent call last):
  File "apps/frappe/frappe/utils/scheduler.py", line 76, in enqueue_events_for_site
    if is_scheduler_inactive():
  File "apps/frappe/frappe/utils/scheduler.py", line 113, in is_scheduler_inactive
    if is_scheduler_disabled():
  File "apps/frappe/frappe/utils/scheduler.py", line 125, in is_scheduler_disabled
    frappe.db.get_single_value("System Settings", "enable_scheduler")
  File "apps/frappe/frappe/database/database.py", line 671, in get_single_value
    val = self.query.get_sql(
  File "apps/frappe/frappe/query_builder/utils.py", line 71, in execute_query
    return frappe.db.sql(query, params, *args, **kwargs)  # nosemgrep
  File "apps/frappe/frappe/database/database.py", line 145, in sql
    self.connect()
  File "apps/frappe/frappe/database/database.py", line 76, in connect
    self._conn = self.get_connection()
  File "apps/frappe/frappe/database/mariadb/database.py", line 78, in get_connection
    conn = pymysql.connect(
  File "env/lib/python3.8/site-packages/pymysql/connections.py", line 353, in __init__
    self.connect()
  File "env/lib/python3.8/site-packages/pymysql/connections.py", line 664, in connect
    raise exc
pymysql.err.OperationalError: (2003, "Can't connect to MySQL server on '127.0.0.1' ([Errno 111] Connection refused)")

2022-04-27 14:36:53,609 ERROR scheduler Exception in Enqueue Events for Site yy.local
Traceback (most recent call last):
  File "env/lib/python3.8/site-packages/pymysql/connections.py", line 613, in connect
    sock = socket.create_connection(
  File "/usr/lib/python3.8/socket.py", line 808, in create_connection
    raise err
  File "/usr/lib/python3.8/socket.py", line 796, in create_connection
    sock.connect(sa)
ConnectionRefusedError: [Errno 111] Connection refused

During handling of the above exception, another exception occurred:

Traceback (most recent call last):
  File "apps/frappe/frappe/utils/scheduler.py", line 76, in enqueue_events_for_site
    if is_scheduler_inactive():
  File "apps/frappe/frappe/utils/scheduler.py", line 113, in is_scheduler_inactive
    if is_scheduler_disabled():
  File "apps/frappe/frappe/utils/scheduler.py", line 125, in is_scheduler_disabled
    frappe.db.get_single_value("System Settings", "enable_scheduler")
  File "apps/frappe/frappe/database/database.py", line 671, in get_single_value
    val = self.query.get_sql(
  File "apps/frappe/frappe/query_builder/utils.py", line 71, in execute_query
    return frappe.db.sql(query, params, *args, **kwargs)  # nosemgrep
  File "apps/frappe/frappe/database/database.py", line 145, in sql
    self.connect()
  File "apps/frappe/frappe/database/database.py", line 76, in connect
    self._conn = self.get_connection()
  File "apps/frappe/frappe/database/mariadb/database.py", line 78, in get_connection
    conn = pymysql.connect(
  File "env/lib/python3.8/site-packages/pymysql/connections.py", line 353, in __init__
    self.connect()
  File "env/lib/python3.8/site-packages/pymysql/connections.py", line 664, in connect
    raise exc
pymysql.err.OperationalError: (2003, "Can't connect to MySQL server on '127.0.0.1' ([Errno 111] Connection refused)")

2022-04-27 14:37:53,715 ERROR scheduler Exception in Enqueue Events for Site yy.local
Traceback (most recent call last):
  File "env/lib/python3.8/site-packages/pymysql/connections.py", line 613, in connect
    sock = socket.create_connection(
  File "/usr/lib/python3.8/socket.py", line 808, in create_connection
    raise err
  File "/usr/lib/python3.8/socket.py", line 796, in create_connection
    sock.connect(sa)
ConnectionRefusedError: [Errno 111] Connection refused

During handling of the above exception, another exception occurred:

Traceback (most recent call last):
  File "apps/frappe/frappe/utils/scheduler.py", line 76, in enqueue_events_for_site
    if is_scheduler_inactive():
  File "apps/frappe/frappe/utils/scheduler.py", line 113, in is_scheduler_inactive
    if is_scheduler_disabled():
  File "apps/frappe/frappe/utils/scheduler.py", line 125, in is_scheduler_disabled
    frappe.db.get_single_value("System Settings", "enable_scheduler")
  File "apps/frappe/frappe/database/database.py", line 671, in get_single_value
    val = self.query.get_sql(
  File "apps/frappe/frappe/query_builder/utils.py", line 71, in execute_query
    return frappe.db.sql(query, params, *args, **kwargs)  # nosemgrep
  File "apps/frappe/frappe/database/database.py", line 145, in sql
    self.connect()
  File "apps/frappe/frappe/database/database.py", line 76, in connect
    self._conn = self.get_connection()
  File "apps/frappe/frappe/database/mariadb/database.py", line 78, in get_connection
    conn = pymysql.connect(
  File "env/lib/python3.8/site-packages/pymysql/connections.py", line 353, in __init__
    self.connect()
  File "env/lib/python3.8/site-packages/pymysql/connections.py", line 664, in connect
    raise exc
pymysql.err.OperationalError: (2003, "Can't connect to MySQL server on '127.0.0.1' ([Errno 111] Connection refused)")

2022-04-27 14:38:53,826 ERROR scheduler Exception in Enqueue Events for Site yy.local
Traceback (most recent call last):
  File "env/lib/python3.8/site-packages/pymysql/connections.py", line 613, in connect
    sock = socket.create_connection(
  File "/usr/lib/python3.8/socket.py", line 808, in create_connection
    raise err
  File "/usr/lib/python3.8/socket.py", line 796, in create_connection
    sock.connect(sa)
ConnectionRefusedError: [Errno 111] Connection refused

During handling of the above exception, another exception occurred:

Traceback (most recent call last):
  File "apps/frappe/frappe/utils/scheduler.py", line 76, in enqueue_events_for_site
    if is_scheduler_inactive():
  File "apps/frappe/frappe/utils/scheduler.py", line 113, in is_scheduler_inactive
    if is_scheduler_disabled():
  File "apps/frappe/frappe/utils/scheduler.py", line 125, in is_scheduler_disabled
    frappe.db.get_single_value("System Settings", "enable_scheduler")
  File "apps/frappe/frappe/database/database.py", line 671, in get_single_value
    val = self.query.get_sql(
  File "apps/frappe/frappe/query_builder/utils.py", line 71, in execute_query
    return frappe.db.sql(query, params, *args, **kwargs)  # nosemgrep
  File "apps/frappe/frappe/database/database.py", line 145, in sql
    self.connect()
  File "apps/frappe/frappe/database/database.py", line 76, in connect
    self._conn = self.get_connection()
  File "apps/frappe/frappe/database/mariadb/database.py", line 78, in get_connection
    conn = pymysql.connect(
  File "env/lib/python3.8/site-packages/pymysql/connections.py", line 353, in __init__
    self.connect()
  File "env/lib/python3.8/site-packages/pymysql/connections.py", line 664, in connect
    raise exc
pymysql.err.OperationalError: (2003, "Can't connect to MySQL server on '127.0.0.1' ([Errno 111] Connection refused)")

2022-04-27 14:39:53,930 ERROR scheduler Exception in Enqueue Events for Site yy.local
Traceback (most recent call last):
  File "env/lib/python3.8/site-packages/pymysql/connections.py", line 613, in connect
    sock = socket.create_connection(
  File "/usr/lib/python3.8/socket.py", line 808, in create_connection
    raise err
  File "/usr/lib/python3.8/socket.py", line 796, in create_connection
    sock.connect(sa)
ConnectionRefusedError: [Errno 111] Connection refused

During handling of the above exception, another exception occurred:

Traceback (most recent call last):
  File "apps/frappe/frappe/utils/scheduler.py", line 76, in enqueue_events_for_site
    if is_scheduler_inactive():
  File "apps/frappe/frappe/utils/scheduler.py", line 113, in is_scheduler_inactive
    if is_scheduler_disabled():
  File "apps/frappe/frappe/utils/scheduler.py", line 125, in is_scheduler_disabled
    frappe.db.get_single_value("System Settings", "enable_scheduler")
  File "apps/frappe/frappe/database/database.py", line 671, in get_single_value
    val = self.query.get_sql(
  File "apps/frappe/frappe/query_builder/utils.py", line 71, in execute_query
    return frappe.db.sql(query, params, *args, **kwargs)  # nosemgrep
  File "apps/frappe/frappe/database/database.py", line 145, in sql
    self.connect()
  File "apps/frappe/frappe/database/database.py", line 76, in connect
    self._conn = self.get_connection()
  File "apps/frappe/frappe/database/mariadb/database.py", line 78, in get_connection
    conn = pymysql.connect(
  File "env/lib/python3.8/site-packages/pymysql/connections.py", line 353, in __init__
    self.connect()
  File "env/lib/python3.8/site-packages/pymysql/connections.py", line 664, in connect
    raise exc
pymysql.err.OperationalError: (2003, "Can't connect to MySQL server on '127.0.0.1' ([Errno 111] Connection refused)")

2022-04-27 14:40:54,029 ERROR scheduler Exception in Enqueue Events for Site yy.local
Traceback (most recent call last):
  File "env/lib/python3.8/site-packages/pymysql/connections.py", line 613, in connect
    sock = socket.create_connection(
  File "/usr/lib/python3.8/socket.py", line 808, in create_connection
    raise err
  File "/usr/lib/python3.8/socket.py", line 796, in create_connection
    sock.connect(sa)
ConnectionRefusedError: [Errno 111] Connection refused

During handling of the above exception, another exception occurred:

Traceback (most recent call last):
  File "apps/frappe/frappe/utils/scheduler.py", line 76, in enqueue_events_for_site
    if is_scheduler_inactive():
  File "apps/frappe/frappe/utils/scheduler.py", line 113, in is_scheduler_inactive
    if is_scheduler_disabled():
  File "apps/frappe/frappe/utils/scheduler.py", line 125, in is_scheduler_disabled
    frappe.db.get_single_value("System Settings", "enable_scheduler")
  File "apps/frappe/frappe/database/database.py", line 671, in get_single_value
    val = self.query.get_sql(
  File "apps/frappe/frappe/query_builder/utils.py", line 71, in execute_query
    return frappe.db.sql(query, params, *args, **kwargs)  # nosemgrep
  File "apps/frappe/frappe/database/database.py", line 145, in sql
    self.connect()
  File "apps/frappe/frappe/database/database.py", line 76, in connect
    self._conn = self.get_connection()
  File "apps/frappe/frappe/database/mariadb/database.py", line 78, in get_connection
    conn = pymysql.connect(
  File "env/lib/python3.8/site-packages/pymysql/connections.py", line 353, in __init__
    self.connect()
  File "env/lib/python3.8/site-packages/pymysql/connections.py", line 664, in connect
    raise exc
pymysql.err.OperationalError: (2003, "Can't connect to MySQL server on '127.0.0.1' ([Errno 111] Connection refused)")

2022-04-27 14:41:54,151 ERROR scheduler Exception in Enqueue Events for Site yy.local
Traceback (most recent call last):
  File "env/lib/python3.8/site-packages/pymysql/connections.py", line 613, in connect
    sock = socket.create_connection(
  File "/usr/lib/python3.8/socket.py", line 808, in create_connection
    raise err
  File "/usr/lib/python3.8/socket.py", line 796, in create_connection
    sock.connect(sa)
ConnectionRefusedError: [Errno 111] Connection refused

During handling of the above exception, another exception occurred:

Traceback (most recent call last):
  File "apps/frappe/frappe/utils/scheduler.py", line 76, in enqueue_events_for_site
    if is_scheduler_inactive():
  File "apps/frappe/frappe/utils/scheduler.py", line 113, in is_scheduler_inactive
    if is_scheduler_disabled():
  File "apps/frappe/frappe/utils/scheduler.py", line 125, in is_scheduler_disabled
    frappe.db.get_single_value("System Settings", "enable_scheduler")
  File "apps/frappe/frappe/database/database.py", line 671, in get_single_value
    val = self.query.get_sql(
  File "apps/frappe/frappe/query_builder/utils.py", line 71, in execute_query
    return frappe.db.sql(query, params, *args, **kwargs)  # nosemgrep
  File "apps/frappe/frappe/database/database.py", line 145, in sql
    self.connect()
  File "apps/frappe/frappe/database/database.py", line 76, in connect
    self._conn = self.get_connection()
  File "apps/frappe/frappe/database/mariadb/database.py", line 78, in get_connection
    conn = pymysql.connect(
  File "env/lib/python3.8/site-packages/pymysql/connections.py", line 353, in __init__
    self.connect()
  File "env/lib/python3.8/site-packages/pymysql/connections.py", line 664, in connect
    raise exc
pymysql.err.OperationalError: (2003, "Can't connect to MySQL server on '127.0.0.1' ([Errno 111] Connection refused)")

2022-04-27 14:42:54,251 ERROR scheduler Exception in Enqueue Events for Site yy.local
Traceback (most recent call last):
  File "env/lib/python3.8/site-packages/pymysql/connections.py", line 613, in connect
    sock = socket.create_connection(
  File "/usr/lib/python3.8/socket.py", line 808, in create_connection
    raise err
  File "/usr/lib/python3.8/socket.py", line 796, in create_connection
    sock.connect(sa)
ConnectionRefusedError: [Errno 111] Connection refused

During handling of the above exception, another exception occurred:

Traceback (most recent call last):
  File "apps/frappe/frappe/utils/scheduler.py", line 76, in enqueue_events_for_site
    if is_scheduler_inactive():
  File "apps/frappe/frappe/utils/scheduler.py", line 113, in is_scheduler_inactive
    if is_scheduler_disabled():
  File "apps/frappe/frappe/utils/scheduler.py", line 125, in is_scheduler_disabled
    frappe.db.get_single_value("System Settings", "enable_scheduler")
  File "apps/frappe/frappe/database/database.py", line 671, in get_single_value
    val = self.query.get_sql(
  File "apps/frappe/frappe/query_builder/utils.py", line 71, in execute_query
    return frappe.db.sql(query, params, *args, **kwargs)  # nosemgrep
  File "apps/frappe/frappe/database/database.py", line 145, in sql
    self.connect()
  File "apps/frappe/frappe/database/database.py", line 76, in connect
    self._conn = self.get_connection()
  File "apps/frappe/frappe/database/mariadb/database.py", line 78, in get_connection
    conn = pymysql.connect(
  File "env/lib/python3.8/site-packages/pymysql/connections.py", line 353, in __init__
    self.connect()
  File "env/lib/python3.8/site-packages/pymysql/connections.py", line 664, in connect
    raise exc
pymysql.err.OperationalError: (2003, "Can't connect to MySQL server on '127.0.0.1' ([Errno 111] Connection refused)")

2022-04-27 14:43:54,366 ERROR scheduler Exception in Enqueue Events for Site yy.local
Traceback (most recent call last):
  File "env/lib/python3.8/site-packages/pymysql/connections.py", line 613, in connect
    sock = socket.create_connection(
  File "/usr/lib/python3.8/socket.py", line 808, in create_connection
    raise err
  File "/usr/lib/python3.8/socket.py", line 796, in create_connection
    sock.connect(sa)
ConnectionRefusedError: [Errno 111] Connection refused

During handling of the above exception, another exception occurred:

Traceback (most recent call last):
  File "apps/frappe/frappe/utils/scheduler.py", line 76, in enqueue_events_for_site
    if is_scheduler_inactive():
  File "apps/frappe/frappe/utils/scheduler.py", line 113, in is_scheduler_inactive
    if is_scheduler_disabled():
  File "apps/frappe/frappe/utils/scheduler.py", line 125, in is_scheduler_disabled
    frappe.db.get_single_value("System Settings", "enable_scheduler")
  File "apps/frappe/frappe/database/database.py", line 671, in get_single_value
    val = self.query.get_sql(
  File "apps/frappe/frappe/query_builder/utils.py", line 71, in execute_query
    return frappe.db.sql(query, params, *args, **kwargs)  # nosemgrep
  File "apps/frappe/frappe/database/database.py", line 145, in sql
    self.connect()
  File "apps/frappe/frappe/database/database.py", line 76, in connect
    self._conn = self.get_connection()
  File "apps/frappe/frappe/database/mariadb/database.py", line 78, in get_connection
    conn = pymysql.connect(
  File "env/lib/python3.8/site-packages/pymysql/connections.py", line 353, in __init__
    self.connect()
  File "env/lib/python3.8/site-packages/pymysql/connections.py", line 664, in connect
    raise exc
pymysql.err.OperationalError: (2003, "Can't connect to MySQL server on '127.0.0.1' ([Errno 111] Connection refused)")

2022-04-27 14:44:54,490 ERROR scheduler Exception in Enqueue Events for Site yy.local
Traceback (most recent call last):
  File "env/lib/python3.8/site-packages/pymysql/connections.py", line 613, in connect
    sock = socket.create_connection(
  File "/usr/lib/python3.8/socket.py", line 808, in create_connection
    raise err
  File "/usr/lib/python3.8/socket.py", line 796, in create_connection
    sock.connect(sa)
ConnectionRefusedError: [Errno 111] Connection refused

During handling of the above exception, another exception occurred:

Traceback (most recent call last):
  File "apps/frappe/frappe/utils/scheduler.py", line 76, in enqueue_events_for_site
    if is_scheduler_inactive():
  File "apps/frappe/frappe/utils/scheduler.py", line 113, in is_scheduler_inactive
    if is_scheduler_disabled():
  File "apps/frappe/frappe/utils/scheduler.py", line 125, in is_scheduler_disabled
    frappe.db.get_single_value("System Settings", "enable_scheduler")
  File "apps/frappe/frappe/database/database.py", line 671, in get_single_value
    val = self.query.get_sql(
  File "apps/frappe/frappe/query_builder/utils.py", line 71, in execute_query
    return frappe.db.sql(query, params, *args, **kwargs)  # nosemgrep
  File "apps/frappe/frappe/database/database.py", line 145, in sql
    self.connect()
  File "apps/frappe/frappe/database/database.py", line 76, in connect
    self._conn = self.get_connection()
  File "apps/frappe/frappe/database/mariadb/database.py", line 78, in get_connection
    conn = pymysql.connect(
  File "env/lib/python3.8/site-packages/pymysql/connections.py", line 353, in __init__
    self.connect()
  File "env/lib/python3.8/site-packages/pymysql/connections.py", line 664, in connect
    raise exc
pymysql.err.OperationalError: (2003, "Can't connect to MySQL server on '127.0.0.1' ([Errno 111] Connection refused)")

2022-04-27 14:45:54,581 ERROR scheduler Exception in Enqueue Events for Site yy.local
Traceback (most recent call last):
  File "env/lib/python3.8/site-packages/pymysql/connections.py", line 613, in connect
    sock = socket.create_connection(
  File "/usr/lib/python3.8/socket.py", line 808, in create_connection
    raise err
  File "/usr/lib/python3.8/socket.py", line 796, in create_connection
    sock.connect(sa)
ConnectionRefusedError: [Errno 111] Connection refused

During handling of the above exception, another exception occurred:

Traceback (most recent call last):
  File "apps/frappe/frappe/utils/scheduler.py", line 76, in enqueue_events_for_site
    if is_scheduler_inactive():
  File "apps/frappe/frappe/utils/scheduler.py", line 113, in is_scheduler_inactive
    if is_scheduler_disabled():
  File "apps/frappe/frappe/utils/scheduler.py", line 125, in is_scheduler_disabled
    frappe.db.get_single_value("System Settings", "enable_scheduler")
  File "apps/frappe/frappe/database/database.py", line 671, in get_single_value
    val = self.query.get_sql(
  File "apps/frappe/frappe/query_builder/utils.py", line 71, in execute_query
    return frappe.db.sql(query, params, *args, **kwargs)  # nosemgrep
  File "apps/frappe/frappe/database/database.py", line 145, in sql
    self.connect()
  File "apps/frappe/frappe/database/database.py", line 76, in connect
    self._conn = self.get_connection()
  File "apps/frappe/frappe/database/mariadb/database.py", line 78, in get_connection
    conn = pymysql.connect(
  File "env/lib/python3.8/site-packages/pymysql/connections.py", line 353, in __init__
    self.connect()
  File "env/lib/python3.8/site-packages/pymysql/connections.py", line 664, in connect
    raise exc
pymysql.err.OperationalError: (2003, "Can't connect to MySQL server on '127.0.0.1' ([Errno 111] Connection refused)")

2022-04-27 14:46:54,683 ERROR scheduler Exception in Enqueue Events for Site yy.local
Traceback (most recent call last):
  File "env/lib/python3.8/site-packages/pymysql/connections.py", line 613, in connect
    sock = socket.create_connection(
  File "/usr/lib/python3.8/socket.py", line 808, in create_connection
    raise err
  File "/usr/lib/python3.8/socket.py", line 796, in create_connection
    sock.connect(sa)
ConnectionRefusedError: [Errno 111] Connection refused

During handling of the above exception, another exception occurred:

Traceback (most recent call last):
  File "apps/frappe/frappe/utils/scheduler.py", line 76, in enqueue_events_for_site
    if is_scheduler_inactive():
  File "apps/frappe/frappe/utils/scheduler.py", line 113, in is_scheduler_inactive
    if is_scheduler_disabled():
  File "apps/frappe/frappe/utils/scheduler.py", line 125, in is_scheduler_disabled
    frappe.db.get_single_value("System Settings", "enable_scheduler")
  File "apps/frappe/frappe/database/database.py", line 671, in get_single_value
    val = self.query.get_sql(
  File "apps/frappe/frappe/query_builder/utils.py", line 71, in execute_query
    return frappe.db.sql(query, params, *args, **kwargs)  # nosemgrep
  File "apps/frappe/frappe/database/database.py", line 145, in sql
    self.connect()
  File "apps/frappe/frappe/database/database.py", line 76, in connect
    self._conn = self.get_connection()
  File "apps/frappe/frappe/database/mariadb/database.py", line 78, in get_connection
    conn = pymysql.connect(
  File "env/lib/python3.8/site-packages/pymysql/connections.py", line 353, in __init__
    self.connect()
  File "env/lib/python3.8/site-packages/pymysql/connections.py", line 664, in connect
    raise exc
pymysql.err.OperationalError: (2003, "Can't connect to MySQL server on '127.0.0.1' ([Errno 111] Connection refused)")

2022-04-27 14:47:54,774 ERROR scheduler Exception in Enqueue Events for Site yy.local
Traceback (most recent call last):
  File "env/lib/python3.8/site-packages/pymysql/connections.py", line 613, in connect
    sock = socket.create_connection(
  File "/usr/lib/python3.8/socket.py", line 808, in create_connection
    raise err
  File "/usr/lib/python3.8/socket.py", line 796, in create_connection
    sock.connect(sa)
ConnectionRefusedError: [Errno 111] Connection refused

During handling of the above exception, another exception occurred:

Traceback (most recent call last):
  File "apps/frappe/frappe/utils/scheduler.py", line 76, in enqueue_events_for_site
    if is_scheduler_inactive():
  File "apps/frappe/frappe/utils/scheduler.py", line 113, in is_scheduler_inactive
    if is_scheduler_disabled():
  File "apps/frappe/frappe/utils/scheduler.py", line 125, in is_scheduler_disabled
    frappe.db.get_single_value("System Settings", "enable_scheduler")
  File "apps/frappe/frappe/database/database.py", line 671, in get_single_value
    val = self.query.get_sql(
  File "apps/frappe/frappe/query_builder/utils.py", line 71, in execute_query
    return frappe.db.sql(query, params, *args, **kwargs)  # nosemgrep
  File "apps/frappe/frappe/database/database.py", line 145, in sql
    self.connect()
  File "apps/frappe/frappe/database/database.py", line 76, in connect
    self._conn = self.get_connection()
  File "apps/frappe/frappe/database/mariadb/database.py", line 78, in get_connection
    conn = pymysql.connect(
  File "env/lib/python3.8/site-packages/pymysql/connections.py", line 353, in __init__
    self.connect()
  File "env/lib/python3.8/site-packages/pymysql/connections.py", line 664, in connect
    raise exc
pymysql.err.OperationalError: (2003, "Can't connect to MySQL server on '127.0.0.1' ([Errno 111] Connection refused)")

2022-04-27 14:48:54,860 ERROR scheduler Exception in Enqueue Events for Site yy.local
Traceback (most recent call last):
  File "env/lib/python3.8/site-packages/pymysql/connections.py", line 613, in connect
    sock = socket.create_connection(
  File "/usr/lib/python3.8/socket.py", line 808, in create_connection
    raise err
  File "/usr/lib/python3.8/socket.py", line 796, in create_connection
    sock.connect(sa)
ConnectionRefusedError: [Errno 111] Connection refused

During handling of the above exception, another exception occurred:

Traceback (most recent call last):
  File "apps/frappe/frappe/utils/scheduler.py", line 76, in enqueue_events_for_site
    if is_scheduler_inactive():
  File "apps/frappe/frappe/utils/scheduler.py", line 113, in is_scheduler_inactive
    if is_scheduler_disabled():
  File "apps/frappe/frappe/utils/scheduler.py", line 125, in is_scheduler_disabled
    frappe.db.get_single_value("System Settings", "enable_scheduler")
  File "apps/frappe/frappe/database/database.py", line 671, in get_single_value
    val = self.query.get_sql(
  File "apps/frappe/frappe/query_builder/utils.py", line 71, in execute_query
    return frappe.db.sql(query, params, *args, **kwargs)  # nosemgrep
  File "apps/frappe/frappe/database/database.py", line 145, in sql
    self.connect()
  File "apps/frappe/frappe/database/database.py", line 76, in connect
    self._conn = self.get_connection()
  File "apps/frappe/frappe/database/mariadb/database.py", line 78, in get_connection
    conn = pymysql.connect(
  File "env/lib/python3.8/site-packages/pymysql/connections.py", line 353, in __init__
    self.connect()
  File "env/lib/python3.8/site-packages/pymysql/connections.py", line 664, in connect
    raise exc
pymysql.err.OperationalError: (2003, "Can't connect to MySQL server on '127.0.0.1' ([Errno 111] Connection refused)")

2022-04-27 14:49:54,995 ERROR scheduler Exception in Enqueue Events for Site yy.local
Traceback (most recent call last):
  File "env/lib/python3.8/site-packages/pymysql/connections.py", line 613, in connect
    sock = socket.create_connection(
  File "/usr/lib/python3.8/socket.py", line 808, in create_connection
    raise err
  File "/usr/lib/python3.8/socket.py", line 796, in create_connection
    sock.connect(sa)
ConnectionRefusedError: [Errno 111] Connection refused

During handling of the above exception, another exception occurred:

Traceback (most recent call last):
  File "apps/frappe/frappe/utils/scheduler.py", line 76, in enqueue_events_for_site
    if is_scheduler_inactive():
  File "apps/frappe/frappe/utils/scheduler.py", line 113, in is_scheduler_inactive
    if is_scheduler_disabled():
  File "apps/frappe/frappe/utils/scheduler.py", line 125, in is_scheduler_disabled
    frappe.db.get_single_value("System Settings", "enable_scheduler")
  File "apps/frappe/frappe/database/database.py", line 671, in get_single_value
    val = self.query.get_sql(
  File "apps/frappe/frappe/query_builder/utils.py", line 71, in execute_query
    return frappe.db.sql(query, params, *args, **kwargs)  # nosemgrep
  File "apps/frappe/frappe/database/database.py", line 145, in sql
    self.connect()
  File "apps/frappe/frappe/database/database.py", line 76, in connect
    self._conn = self.get_connection()
  File "apps/frappe/frappe/database/mariadb/database.py", line 78, in get_connection
    conn = pymysql.connect(
  File "env/lib/python3.8/site-packages/pymysql/connections.py", line 353, in __init__
    self.connect()
  File "env/lib/python3.8/site-packages/pymysql/connections.py", line 664, in connect
    raise exc
pymysql.err.OperationalError: (2003, "Can't connect to MySQL server on '127.0.0.1' ([Errno 111] Connection refused)")

2022-04-27 14:50:55,119 ERROR scheduler Exception in Enqueue Events for Site yy.local
Traceback (most recent call last):
  File "env/lib/python3.8/site-packages/pymysql/connections.py", line 613, in connect
    sock = socket.create_connection(
  File "/usr/lib/python3.8/socket.py", line 808, in create_connection
    raise err
  File "/usr/lib/python3.8/socket.py", line 796, in create_connection
    sock.connect(sa)
ConnectionRefusedError: [Errno 111] Connection refused

During handling of the above exception, another exception occurred:

Traceback (most recent call last):
  File "apps/frappe/frappe/utils/scheduler.py", line 76, in enqueue_events_for_site
    if is_scheduler_inactive():
  File "apps/frappe/frappe/utils/scheduler.py", line 113, in is_scheduler_inactive
    if is_scheduler_disabled():
  File "apps/frappe/frappe/utils/scheduler.py", line 125, in is_scheduler_disabled
    frappe.db.get_single_value("System Settings", "enable_scheduler")
  File "apps/frappe/frappe/database/database.py", line 671, in get_single_value
    val = self.query.get_sql(
  File "apps/frappe/frappe/query_builder/utils.py", line 71, in execute_query
    return frappe.db.sql(query, params, *args, **kwargs)  # nosemgrep
  File "apps/frappe/frappe/database/database.py", line 145, in sql
    self.connect()
  File "apps/frappe/frappe/database/database.py", line 76, in connect
    self._conn = self.get_connection()
  File "apps/frappe/frappe/database/mariadb/database.py", line 78, in get_connection
    conn = pymysql.connect(
  File "env/lib/python3.8/site-packages/pymysql/connections.py", line 353, in __init__
    self.connect()
  File "env/lib/python3.8/site-packages/pymysql/connections.py", line 664, in connect
    raise exc
pymysql.err.OperationalError: (2003, "Can't connect to MySQL server on '127.0.0.1' ([Errno 111] Connection refused)")

2022-04-27 14:51:55,269 ERROR scheduler Exception in Enqueue Events for Site yy.local
Traceback (most recent call last):
  File "env/lib/python3.8/site-packages/pymysql/connections.py", line 613, in connect
    sock = socket.create_connection(
  File "/usr/lib/python3.8/socket.py", line 808, in create_connection
    raise err
  File "/usr/lib/python3.8/socket.py", line 796, in create_connection
    sock.connect(sa)
ConnectionRefusedError: [Errno 111] Connection refused

During handling of the above exception, another exception occurred:

Traceback (most recent call last):
  File "apps/frappe/frappe/utils/scheduler.py", line 76, in enqueue_events_for_site
    if is_scheduler_inactive():
  File "apps/frappe/frappe/utils/scheduler.py", line 113, in is_scheduler_inactive
    if is_scheduler_disabled():
  File "apps/frappe/frappe/utils/scheduler.py", line 125, in is_scheduler_disabled
    frappe.db.get_single_value("System Settings", "enable_scheduler")
  File "apps/frappe/frappe/database/database.py", line 671, in get_single_value
    val = self.query.get_sql(
  File "apps/frappe/frappe/query_builder/utils.py", line 71, in execute_query
    return frappe.db.sql(query, params, *args, **kwargs)  # nosemgrep
  File "apps/frappe/frappe/database/database.py", line 145, in sql
    self.connect()
  File "apps/frappe/frappe/database/database.py", line 76, in connect
    self._conn = self.get_connection()
  File "apps/frappe/frappe/database/mariadb/database.py", line 78, in get_connection
    conn = pymysql.connect(
  File "env/lib/python3.8/site-packages/pymysql/connections.py", line 353, in __init__
    self.connect()
  File "env/lib/python3.8/site-packages/pymysql/connections.py", line 664, in connect
    raise exc
pymysql.err.OperationalError: (2003, "Can't connect to MySQL server on '127.0.0.1' ([Errno 111] Connection refused)")

2022-04-27 14:52:55,384 ERROR scheduler Exception in Enqueue Events for Site yy.local
Traceback (most recent call last):
  File "env/lib/python3.8/site-packages/pymysql/connections.py", line 613, in connect
    sock = socket.create_connection(
  File "/usr/lib/python3.8/socket.py", line 808, in create_connection
    raise err
  File "/usr/lib/python3.8/socket.py", line 796, in create_connection
    sock.connect(sa)
ConnectionRefusedError: [Errno 111] Connection refused

During handling of the above exception, another exception occurred:

Traceback (most recent call last):
  File "apps/frappe/frappe/utils/scheduler.py", line 76, in enqueue_events_for_site
    if is_scheduler_inactive():
  File "apps/frappe/frappe/utils/scheduler.py", line 113, in is_scheduler_inactive
    if is_scheduler_disabled():
  File "apps/frappe/frappe/utils/scheduler.py", line 125, in is_scheduler_disabled
    frappe.db.get_single_value("System Settings", "enable_scheduler")
  File "apps/frappe/frappe/database/database.py", line 671, in get_single_value
    val = self.query.get_sql(
  File "apps/frappe/frappe/query_builder/utils.py", line 71, in execute_query
    return frappe.db.sql(query, params, *args, **kwargs)  # nosemgrep
  File "apps/frappe/frappe/database/database.py", line 145, in sql
    self.connect()
  File "apps/frappe/frappe/database/database.py", line 76, in connect
    self._conn = self.get_connection()
  File "apps/frappe/frappe/database/mariadb/database.py", line 78, in get_connection
    conn = pymysql.connect(
  File "env/lib/python3.8/site-packages/pymysql/connections.py", line 353, in __init__
    self.connect()
  File "env/lib/python3.8/site-packages/pymysql/connections.py", line 664, in connect
    raise exc
pymysql.err.OperationalError: (2003, "Can't connect to MySQL server on '127.0.0.1' ([Errno 111] Connection refused)")

2022-04-27 14:53:55,521 ERROR scheduler Exception in Enqueue Events for Site yy.local
Traceback (most recent call last):
  File "env/lib/python3.8/site-packages/pymysql/connections.py", line 613, in connect
    sock = socket.create_connection(
  File "/usr/lib/python3.8/socket.py", line 808, in create_connection
    raise err
  File "/usr/lib/python3.8/socket.py", line 796, in create_connection
    sock.connect(sa)
ConnectionRefusedError: [Errno 111] Connection refused

During handling of the above exception, another exception occurred:

Traceback (most recent call last):
  File "apps/frappe/frappe/utils/scheduler.py", line 76, in enqueue_events_for_site
    if is_scheduler_inactive():
  File "apps/frappe/frappe/utils/scheduler.py", line 113, in is_scheduler_inactive
    if is_scheduler_disabled():
  File "apps/frappe/frappe/utils/scheduler.py", line 125, in is_scheduler_disabled
    frappe.db.get_single_value("System Settings", "enable_scheduler")
  File "apps/frappe/frappe/database/database.py", line 671, in get_single_value
    val = self.query.get_sql(
  File "apps/frappe/frappe/query_builder/utils.py", line 71, in execute_query
    return frappe.db.sql(query, params, *args, **kwargs)  # nosemgrep
  File "apps/frappe/frappe/database/database.py", line 145, in sql
    self.connect()
  File "apps/frappe/frappe/database/database.py", line 76, in connect
    self._conn = self.get_connection()
  File "apps/frappe/frappe/database/mariadb/database.py", line 78, in get_connection
    conn = pymysql.connect(
  File "env/lib/python3.8/site-packages/pymysql/connections.py", line 353, in __init__
    self.connect()
  File "env/lib/python3.8/site-packages/pymysql/connections.py", line 664, in connect
    raise exc
pymysql.err.OperationalError: (2003, "Can't connect to MySQL server on '127.0.0.1' ([Errno 111] Connection refused)")

2022-04-27 14:54:55,658 ERROR scheduler Exception in Enqueue Events for Site yy.local
Traceback (most recent call last):
  File "env/lib/python3.8/site-packages/pymysql/connections.py", line 613, in connect
    sock = socket.create_connection(
  File "/usr/lib/python3.8/socket.py", line 808, in create_connection
    raise err
  File "/usr/lib/python3.8/socket.py", line 796, in create_connection
    sock.connect(sa)
ConnectionRefusedError: [Errno 111] Connection refused

During handling of the above exception, another exception occurred:

Traceback (most recent call last):
  File "apps/frappe/frappe/utils/scheduler.py", line 76, in enqueue_events_for_site
    if is_scheduler_inactive():
  File "apps/frappe/frappe/utils/scheduler.py", line 113, in is_scheduler_inactive
    if is_scheduler_disabled():
  File "apps/frappe/frappe/utils/scheduler.py", line 125, in is_scheduler_disabled
    frappe.db.get_single_value("System Settings", "enable_scheduler")
  File "apps/frappe/frappe/database/database.py", line 671, in get_single_value
    val = self.query.get_sql(
  File "apps/frappe/frappe/query_builder/utils.py", line 71, in execute_query
    return frappe.db.sql(query, params, *args, **kwargs)  # nosemgrep
  File "apps/frappe/frappe/database/database.py", line 145, in sql
    self.connect()
  File "apps/frappe/frappe/database/database.py", line 76, in connect
    self._conn = self.get_connection()
  File "apps/frappe/frappe/database/mariadb/database.py", line 78, in get_connection
    conn = pymysql.connect(
  File "env/lib/python3.8/site-packages/pymysql/connections.py", line 353, in __init__
    self.connect()
  File "env/lib/python3.8/site-packages/pymysql/connections.py", line 664, in connect
    raise exc
pymysql.err.OperationalError: (2003, "Can't connect to MySQL server on '127.0.0.1' ([Errno 111] Connection refused)")

2022-04-27 14:55:55,750 ERROR scheduler Exception in Enqueue Events for Site yy.local
Traceback (most recent call last):
  File "env/lib/python3.8/site-packages/pymysql/connections.py", line 613, in connect
    sock = socket.create_connection(
  File "/usr/lib/python3.8/socket.py", line 808, in create_connection
    raise err
  File "/usr/lib/python3.8/socket.py", line 796, in create_connection
    sock.connect(sa)
ConnectionRefusedError: [Errno 111] Connection refused

During handling of the above exception, another exception occurred:

Traceback (most recent call last):
  File "apps/frappe/frappe/utils/scheduler.py", line 76, in enqueue_events_for_site
    if is_scheduler_inactive():
  File "apps/frappe/frappe/utils/scheduler.py", line 113, in is_scheduler_inactive
    if is_scheduler_disabled():
  File "apps/frappe/frappe/utils/scheduler.py", line 125, in is_scheduler_disabled
    frappe.db.get_single_value("System Settings", "enable_scheduler")
  File "apps/frappe/frappe/database/database.py", line 671, in get_single_value
    val = self.query.get_sql(
  File "apps/frappe/frappe/query_builder/utils.py", line 71, in execute_query
    return frappe.db.sql(query, params, *args, **kwargs)  # nosemgrep
  File "apps/frappe/frappe/database/database.py", line 145, in sql
    self.connect()
  File "apps/frappe/frappe/database/database.py", line 76, in connect
    self._conn = self.get_connection()
  File "apps/frappe/frappe/database/mariadb/database.py", line 78, in get_connection
    conn = pymysql.connect(
  File "env/lib/python3.8/site-packages/pymysql/connections.py", line 353, in __init__
    self.connect()
  File "env/lib/python3.8/site-packages/pymysql/connections.py", line 664, in connect
    raise exc
pymysql.err.OperationalError: (2003, "Can't connect to MySQL server on '127.0.0.1' ([Errno 111] Connection refused)")

2022-04-27 14:56:55,884 ERROR scheduler Exception in Enqueue Events for Site yy.local
Traceback (most recent call last):
  File "env/lib/python3.8/site-packages/pymysql/connections.py", line 613, in connect
    sock = socket.create_connection(
  File "/usr/lib/python3.8/socket.py", line 808, in create_connection
    raise err
  File "/usr/lib/python3.8/socket.py", line 796, in create_connection
    sock.connect(sa)
ConnectionRefusedError: [Errno 111] Connection refused

During handling of the above exception, another exception occurred:

Traceback (most recent call last):
  File "apps/frappe/frappe/utils/scheduler.py", line 76, in enqueue_events_for_site
    if is_scheduler_inactive():
  File "apps/frappe/frappe/utils/scheduler.py", line 113, in is_scheduler_inactive
    if is_scheduler_disabled():
  File "apps/frappe/frappe/utils/scheduler.py", line 125, in is_scheduler_disabled
    frappe.db.get_single_value("System Settings", "enable_scheduler")
  File "apps/frappe/frappe/database/database.py", line 671, in get_single_value
    val = self.query.get_sql(
  File "apps/frappe/frappe/query_builder/utils.py", line 71, in execute_query
    return frappe.db.sql(query, params, *args, **kwargs)  # nosemgrep
  File "apps/frappe/frappe/database/database.py", line 145, in sql
    self.connect()
  File "apps/frappe/frappe/database/database.py", line 76, in connect
    self._conn = self.get_connection()
  File "apps/frappe/frappe/database/mariadb/database.py", line 78, in get_connection
    conn = pymysql.connect(
  File "env/lib/python3.8/site-packages/pymysql/connections.py", line 353, in __init__
    self.connect()
  File "env/lib/python3.8/site-packages/pymysql/connections.py", line 664, in connect
    raise exc
pymysql.err.OperationalError: (2003, "Can't connect to MySQL server on '127.0.0.1' ([Errno 111] Connection refused)")

2022-04-27 14:57:56,013 ERROR scheduler Exception in Enqueue Events for Site yy.local
Traceback (most recent call last):
  File "env/lib/python3.8/site-packages/pymysql/connections.py", line 613, in connect
    sock = socket.create_connection(
  File "/usr/lib/python3.8/socket.py", line 808, in create_connection
    raise err
  File "/usr/lib/python3.8/socket.py", line 796, in create_connection
    sock.connect(sa)
ConnectionRefusedError: [Errno 111] Connection refused

During handling of the above exception, another exception occurred:

Traceback (most recent call last):
  File "apps/frappe/frappe/utils/scheduler.py", line 76, in enqueue_events_for_site
    if is_scheduler_inactive():
  File "apps/frappe/frappe/utils/scheduler.py", line 113, in is_scheduler_inactive
    if is_scheduler_disabled():
  File "apps/frappe/frappe/utils/scheduler.py", line 125, in is_scheduler_disabled
    frappe.db.get_single_value("System Settings", "enable_scheduler")
  File "apps/frappe/frappe/database/database.py", line 671, in get_single_value
    val = self.query.get_sql(
  File "apps/frappe/frappe/query_builder/utils.py", line 71, in execute_query
    return frappe.db.sql(query, params, *args, **kwargs)  # nosemgrep
  File "apps/frappe/frappe/database/database.py", line 145, in sql
    self.connect()
  File "apps/frappe/frappe/database/database.py", line 76, in connect
    self._conn = self.get_connection()
  File "apps/frappe/frappe/database/mariadb/database.py", line 78, in get_connection
    conn = pymysql.connect(
  File "env/lib/python3.8/site-packages/pymysql/connections.py", line 353, in __init__
    self.connect()
  File "env/lib/python3.8/site-packages/pymysql/connections.py", line 664, in connect
    raise exc
pymysql.err.OperationalError: (2003, "Can't connect to MySQL server on '127.0.0.1' ([Errno 111] Connection refused)")

2022-04-27 14:58:56,148 ERROR scheduler Exception in Enqueue Events for Site yy.local
Traceback (most recent call last):
  File "env/lib/python3.8/site-packages/pymysql/connections.py", line 613, in connect
    sock = socket.create_connection(
  File "/usr/lib/python3.8/socket.py", line 808, in create_connection
    raise err
  File "/usr/lib/python3.8/socket.py", line 796, in create_connection
    sock.connect(sa)
ConnectionRefusedError: [Errno 111] Connection refused

During handling of the above exception, another exception occurred:

Traceback (most recent call last):
  File "apps/frappe/frappe/utils/scheduler.py", line 76, in enqueue_events_for_site
    if is_scheduler_inactive():
  File "apps/frappe/frappe/utils/scheduler.py", line 113, in is_scheduler_inactive
    if is_scheduler_disabled():
  File "apps/frappe/frappe/utils/scheduler.py", line 125, in is_scheduler_disabled
    frappe.db.get_single_value("System Settings", "enable_scheduler")
  File "apps/frappe/frappe/database/database.py", line 671, in get_single_value
    val = self.query.get_sql(
  File "apps/frappe/frappe/query_builder/utils.py", line 71, in execute_query
    return frappe.db.sql(query, params, *args, **kwargs)  # nosemgrep
  File "apps/frappe/frappe/database/database.py", line 145, in sql
    self.connect()
  File "apps/frappe/frappe/database/database.py", line 76, in connect
    self._conn = self.get_connection()
  File "apps/frappe/frappe/database/mariadb/database.py", line 78, in get_connection
    conn = pymysql.connect(
  File "env/lib/python3.8/site-packages/pymysql/connections.py", line 353, in __init__
    self.connect()
  File "env/lib/python3.8/site-packages/pymysql/connections.py", line 664, in connect
    raise exc
pymysql.err.OperationalError: (2003, "Can't connect to MySQL server on '127.0.0.1' ([Errno 111] Connection refused)")

2022-04-27 14:59:56,273 ERROR scheduler Exception in Enqueue Events for Site yy.local
Traceback (most recent call last):
  File "env/lib/python3.8/site-packages/pymysql/connections.py", line 613, in connect
    sock = socket.create_connection(
  File "/usr/lib/python3.8/socket.py", line 808, in create_connection
    raise err
  File "/usr/lib/python3.8/socket.py", line 796, in create_connection
    sock.connect(sa)
ConnectionRefusedError: [Errno 111] Connection refused

During handling of the above exception, another exception occurred:

Traceback (most recent call last):
  File "apps/frappe/frappe/utils/scheduler.py", line 76, in enqueue_events_for_site
    if is_scheduler_inactive():
  File "apps/frappe/frappe/utils/scheduler.py", line 113, in is_scheduler_inactive
    if is_scheduler_disabled():
  File "apps/frappe/frappe/utils/scheduler.py", line 125, in is_scheduler_disabled
    frappe.db.get_single_value("System Settings", "enable_scheduler")
  File "apps/frappe/frappe/database/database.py", line 671, in get_single_value
    val = self.query.get_sql(
  File "apps/frappe/frappe/query_builder/utils.py", line 71, in execute_query
    return frappe.db.sql(query, params, *args, **kwargs)  # nosemgrep
  File "apps/frappe/frappe/database/database.py", line 145, in sql
    self.connect()
  File "apps/frappe/frappe/database/database.py", line 76, in connect
    self._conn = self.get_connection()
  File "apps/frappe/frappe/database/mariadb/database.py", line 78, in get_connection
    conn = pymysql.connect(
  File "env/lib/python3.8/site-packages/pymysql/connections.py", line 353, in __init__
    self.connect()
  File "env/lib/python3.8/site-packages/pymysql/connections.py", line 664, in connect
    raise exc
pymysql.err.OperationalError: (2003, "Can't connect to MySQL server on '127.0.0.1' ([Errno 111] Connection refused)")

2022-04-27 15:00:56,388 ERROR scheduler Exception in Enqueue Events for Site yy.local
Traceback (most recent call last):
  File "env/lib/python3.8/site-packages/pymysql/connections.py", line 613, in connect
    sock = socket.create_connection(
  File "/usr/lib/python3.8/socket.py", line 808, in create_connection
    raise err
  File "/usr/lib/python3.8/socket.py", line 796, in create_connection
    sock.connect(sa)
ConnectionRefusedError: [Errno 111] Connection refused

During handling of the above exception, another exception occurred:

Traceback (most recent call last):
  File "apps/frappe/frappe/utils/scheduler.py", line 76, in enqueue_events_for_site
    if is_scheduler_inactive():
  File "apps/frappe/frappe/utils/scheduler.py", line 113, in is_scheduler_inactive
    if is_scheduler_disabled():
  File "apps/frappe/frappe/utils/scheduler.py", line 125, in is_scheduler_disabled
    frappe.db.get_single_value("System Settings", "enable_scheduler")
  File "apps/frappe/frappe/database/database.py", line 671, in get_single_value
    val = self.query.get_sql(
  File "apps/frappe/frappe/query_builder/utils.py", line 71, in execute_query
    return frappe.db.sql(query, params, *args, **kwargs)  # nosemgrep
  File "apps/frappe/frappe/database/database.py", line 145, in sql
    self.connect()
  File "apps/frappe/frappe/database/database.py", line 76, in connect
    self._conn = self.get_connection()
  File "apps/frappe/frappe/database/mariadb/database.py", line 78, in get_connection
    conn = pymysql.connect(
  File "env/lib/python3.8/site-packages/pymysql/connections.py", line 353, in __init__
    self.connect()
  File "env/lib/python3.8/site-packages/pymysql/connections.py", line 664, in connect
    raise exc
pymysql.err.OperationalError: (2003, "Can't connect to MySQL server on '127.0.0.1' ([Errno 111] Connection refused)")

2022-04-27 15:01:56,498 ERROR scheduler Exception in Enqueue Events for Site yy.local
Traceback (most recent call last):
  File "env/lib/python3.8/site-packages/pymysql/connections.py", line 613, in connect
    sock = socket.create_connection(
  File "/usr/lib/python3.8/socket.py", line 808, in create_connection
    raise err
  File "/usr/lib/python3.8/socket.py", line 796, in create_connection
    sock.connect(sa)
ConnectionRefusedError: [Errno 111] Connection refused

During handling of the above exception, another exception occurred:

Traceback (most recent call last):
  File "apps/frappe/frappe/utils/scheduler.py", line 76, in enqueue_events_for_site
    if is_scheduler_inactive():
  File "apps/frappe/frappe/utils/scheduler.py", line 113, in is_scheduler_inactive
    if is_scheduler_disabled():
  File "apps/frappe/frappe/utils/scheduler.py", line 125, in is_scheduler_disabled
    frappe.db.get_single_value("System Settings", "enable_scheduler")
  File "apps/frappe/frappe/database/database.py", line 671, in get_single_value
    val = self.query.get_sql(
  File "apps/frappe/frappe/query_builder/utils.py", line 71, in execute_query
    return frappe.db.sql(query, params, *args, **kwargs)  # nosemgrep
  File "apps/frappe/frappe/database/database.py", line 145, in sql
    self.connect()
  File "apps/frappe/frappe/database/database.py", line 76, in connect
    self._conn = self.get_connection()
  File "apps/frappe/frappe/database/mariadb/database.py", line 78, in get_connection
    conn = pymysql.connect(
  File "env/lib/python3.8/site-packages/pymysql/connections.py", line 353, in __init__
    self.connect()
  File "env/lib/python3.8/site-packages/pymysql/connections.py", line 664, in connect
    raise exc
pymysql.err.OperationalError: (2003, "Can't connect to MySQL server on '127.0.0.1' ([Errno 111] Connection refused)")

2022-04-27 15:02:56,588 ERROR scheduler Exception in Enqueue Events for Site yy.local
Traceback (most recent call last):
  File "apps/frappe/frappe/utils/scheduler.py", line 76, in enqueue_events_for_site
    if is_scheduler_inactive():
  File "apps/frappe/frappe/utils/scheduler.py", line 113, in is_scheduler_inactive
    if is_scheduler_disabled():
  File "apps/frappe/frappe/utils/scheduler.py", line 125, in is_scheduler_disabled
    frappe.db.get_single_value("System Settings", "enable_scheduler")
  File "apps/frappe/frappe/database/database.py", line 671, in get_single_value
    val = self.query.get_sql(
  File "apps/frappe/frappe/query_builder/utils.py", line 71, in execute_query
    return frappe.db.sql(query, params, *args, **kwargs)  # nosemgrep
  File "apps/frappe/frappe/database/database.py", line 145, in sql
    self.connect()
  File "apps/frappe/frappe/database/database.py", line 76, in connect
    self._conn = self.get_connection()
  File "apps/frappe/frappe/database/mariadb/database.py", line 78, in get_connection
    conn = pymysql.connect(
  File "env/lib/python3.8/site-packages/pymysql/connections.py", line 353, in __init__
    self.connect()
  File "env/lib/python3.8/site-packages/pymysql/connections.py", line 633, in connect
    self._request_authentication()
  File "env/lib/python3.8/site-packages/pymysql/connections.py", line 907, in _request_authentication
    auth_packet = self._read_packet()
  File "env/lib/python3.8/site-packages/pymysql/connections.py", line 725, in _read_packet
    packet.raise_for_error()
  File "env/lib/python3.8/site-packages/pymysql/protocol.py", line 221, in raise_for_error
    err.raise_mysql_exception(self._data)
  File "env/lib/python3.8/site-packages/pymysql/err.py", line 143, in raise_mysql_exception
    raise errorclass(errno, errval)
pymysql.err.OperationalError: (1698, "Access denied for user '_770670234724b2a9'@'localhost'")

2022-04-27 15:03:56,700 ERROR scheduler Exception in Enqueue Events for Site yy.local
Traceback (most recent call last):
  File "apps/frappe/frappe/utils/scheduler.py", line 76, in enqueue_events_for_site
    if is_scheduler_inactive():
  File "apps/frappe/frappe/utils/scheduler.py", line 113, in is_scheduler_inactive
    if is_scheduler_disabled():
  File "apps/frappe/frappe/utils/scheduler.py", line 125, in is_scheduler_disabled
    frappe.db.get_single_value("System Settings", "enable_scheduler")
  File "apps/frappe/frappe/database/database.py", line 671, in get_single_value
    val = self.query.get_sql(
  File "apps/frappe/frappe/query_builder/utils.py", line 71, in execute_query
    return frappe.db.sql(query, params, *args, **kwargs)  # nosemgrep
  File "apps/frappe/frappe/database/database.py", line 145, in sql
    self.connect()
  File "apps/frappe/frappe/database/database.py", line 76, in connect
    self._conn = self.get_connection()
  File "apps/frappe/frappe/database/mariadb/database.py", line 78, in get_connection
    conn = pymysql.connect(
  File "env/lib/python3.8/site-packages/pymysql/connections.py", line 353, in __init__
    self.connect()
  File "env/lib/python3.8/site-packages/pymysql/connections.py", line 633, in connect
    self._request_authentication()
  File "env/lib/python3.8/site-packages/pymysql/connections.py", line 907, in _request_authentication
    auth_packet = self._read_packet()
  File "env/lib/python3.8/site-packages/pymysql/connections.py", line 725, in _read_packet
    packet.raise_for_error()
  File "env/lib/python3.8/site-packages/pymysql/protocol.py", line 221, in raise_for_error
    err.raise_mysql_exception(self._data)
  File "env/lib/python3.8/site-packages/pymysql/err.py", line 143, in raise_mysql_exception
    raise errorclass(errno, errval)
pymysql.err.OperationalError: (1698, "Access denied for user '_770670234724b2a9'@'localhost'")

2022-04-27 15:04:56,802 ERROR scheduler Exception in Enqueue Events for Site yy.local
Traceback (most recent call last):
  File "apps/frappe/frappe/utils/scheduler.py", line 76, in enqueue_events_for_site
    if is_scheduler_inactive():
  File "apps/frappe/frappe/utils/scheduler.py", line 113, in is_scheduler_inactive
    if is_scheduler_disabled():
  File "apps/frappe/frappe/utils/scheduler.py", line 125, in is_scheduler_disabled
    frappe.db.get_single_value("System Settings", "enable_scheduler")
  File "apps/frappe/frappe/database/database.py", line 671, in get_single_value
    val = self.query.get_sql(
  File "apps/frappe/frappe/query_builder/utils.py", line 71, in execute_query
    return frappe.db.sql(query, params, *args, **kwargs)  # nosemgrep
  File "apps/frappe/frappe/database/database.py", line 145, in sql
    self.connect()
  File "apps/frappe/frappe/database/database.py", line 76, in connect
    self._conn = self.get_connection()
  File "apps/frappe/frappe/database/mariadb/database.py", line 78, in get_connection
    conn = pymysql.connect(
  File "env/lib/python3.8/site-packages/pymysql/connections.py", line 353, in __init__
    self.connect()
  File "env/lib/python3.8/site-packages/pymysql/connections.py", line 633, in connect
    self._request_authentication()
  File "env/lib/python3.8/site-packages/pymysql/connections.py", line 907, in _request_authentication
    auth_packet = self._read_packet()
  File "env/lib/python3.8/site-packages/pymysql/connections.py", line 725, in _read_packet
    packet.raise_for_error()
  File "env/lib/python3.8/site-packages/pymysql/protocol.py", line 221, in raise_for_error
    err.raise_mysql_exception(self._data)
  File "env/lib/python3.8/site-packages/pymysql/err.py", line 143, in raise_mysql_exception
    raise errorclass(errno, errval)
pymysql.err.OperationalError: (1698, "Access denied for user '_770670234724b2a9'@'localhost'")

2022-04-27 15:05:56,901 ERROR scheduler Exception in Enqueue Events for Site yy.local
Traceback (most recent call last):
  File "apps/frappe/frappe/utils/scheduler.py", line 76, in enqueue_events_for_site
    if is_scheduler_inactive():
  File "apps/frappe/frappe/utils/scheduler.py", line 113, in is_scheduler_inactive
    if is_scheduler_disabled():
  File "apps/frappe/frappe/utils/scheduler.py", line 125, in is_scheduler_disabled
    frappe.db.get_single_value("System Settings", "enable_scheduler")
  File "apps/frappe/frappe/database/database.py", line 671, in get_single_value
    val = self.query.get_sql(
  File "apps/frappe/frappe/query_builder/utils.py", line 71, in execute_query
    return frappe.db.sql(query, params, *args, **kwargs)  # nosemgrep
  File "apps/frappe/frappe/database/database.py", line 145, in sql
    self.connect()
  File "apps/frappe/frappe/database/database.py", line 76, in connect
    self._conn = self.get_connection()
  File "apps/frappe/frappe/database/mariadb/database.py", line 78, in get_connection
    conn = pymysql.connect(
  File "env/lib/python3.8/site-packages/pymysql/connections.py", line 353, in __init__
    self.connect()
  File "env/lib/python3.8/site-packages/pymysql/connections.py", line 633, in connect
    self._request_authentication()
  File "env/lib/python3.8/site-packages/pymysql/connections.py", line 907, in _request_authentication
    auth_packet = self._read_packet()
  File "env/lib/python3.8/site-packages/pymysql/connections.py", line 725, in _read_packet
    packet.raise_for_error()
  File "env/lib/python3.8/site-packages/pymysql/protocol.py", line 221, in raise_for_error
    err.raise_mysql_exception(self._data)
  File "env/lib/python3.8/site-packages/pymysql/err.py", line 143, in raise_mysql_exception
    raise errorclass(errno, errval)
pymysql.err.OperationalError: (1698, "Access denied for user '_770670234724b2a9'@'localhost'")

